
Name of the cluster on which the job is executing:
	 spartan
Number of CPUs on the allocated node: 
	 1
Number of CPUs requested per task: 
	 1
Numer of GPUs requested: 
	 
Requested GPU count per allocated node: 
	 
Requested GPU count per allocated task:
	  
The ID of the job allocation:
	  53588017
Count of processors available to the job on this node:
	  1
Name of the job:
	  tst.slurm
List of nodes allocated to the job:
	  spartan-gpgpu079
Total number of nodes in the job’s resource allocation:
	  1
Name of the partition in which the job is running:
	  deeplearn
Minimum memory required per allocated CPU:
	  4000
Requested memory per allocated GPU:
	  
Total amount of memory per node that the job needs:
	  
List of nodes allocated to the job:
	  spartan-gpgpu079
Total number of CPUs allocated:
	  1
Maximum number of MPI tasks (that’s processes): 
	 1
Number of tasks requested per core: 
	 
Number of tasks requested per GPU: 
	 
Number of tasks requested per node:
	  1
The scheduling priority (nice value) at the time of job submission. This value is propagated to the spawned processes: 
	 0
The MPI rank (or relative process ID) of the current process: 
	 0
The directory from which SBATCH was invoked: 
	 /data/gpfs/projects/punim1355/dalmiapriyam/predator-prey
The Hostname of the computer from which SBATCH was invoked: 
	 spartan-login2.hpc.unimelb.edu.au
The process ID of the corresponding task: 
	 95383



 LOADING MODULES: 




 PYTHON SCRIPT OUTPUT: 

2023-11-19 17:43:40,667	INFO worker.py:1673 -- Started a local Ray instance.
CPU Affinity: [2]
Traceback (most recent call last):
  File "/data/gpfs/projects/punim1355/dalmiapriyam/predator-prey/.venv/lib/python3.10/site-packages/urllib3/connection.py", line 203, in _new_conn
    sock = connection.create_connection(
  File "/data/gpfs/projects/punim1355/dalmiapriyam/predator-prey/.venv/lib/python3.10/site-packages/urllib3/util/connection.py", line 85, in create_connection
    raise err
  File "/data/gpfs/projects/punim1355/dalmiapriyam/predator-prey/.venv/lib/python3.10/site-packages/urllib3/util/connection.py", line 73, in create_connection
    sock.connect(sa)
ConnectionRefusedError: [Errno 111] Connection refused

The above exception was the direct cause of the following exception:

Traceback (most recent call last):
  File "/data/gpfs/projects/punim1355/dalmiapriyam/predator-prey/.venv/lib/python3.10/site-packages/urllib3/connectionpool.py", line 790, in urlopen
    response = self._make_request(
  File "/data/gpfs/projects/punim1355/dalmiapriyam/predator-prey/.venv/lib/python3.10/site-packages/urllib3/connectionpool.py", line 496, in _make_request
    conn.request(
  File "/data/gpfs/projects/punim1355/dalmiapriyam/predator-prey/.venv/lib/python3.10/site-packages/urllib3/connection.py", line 395, in request
    self.endheaders()
  File "/apps/easybuild-2022/easybuild/software/Compiler/GCCcore/11.3.0/Python/3.10.4/lib/python3.10/http/client.py", line 1277, in endheaders
    self._send_output(message_body, encode_chunked=encode_chunked)
  File "/apps/easybuild-2022/easybuild/software/Compiler/GCCcore/11.3.0/Python/3.10.4/lib/python3.10/http/client.py", line 1037, in _send_output
    self.send(msg)
  File "/apps/easybuild-2022/easybuild/software/Compiler/GCCcore/11.3.0/Python/3.10.4/lib/python3.10/http/client.py", line 975, in send
    self.connect()
  File "/data/gpfs/projects/punim1355/dalmiapriyam/predator-prey/.venv/lib/python3.10/site-packages/urllib3/connection.py", line 243, in connect
    self.sock = self._new_conn()
  File "/data/gpfs/projects/punim1355/dalmiapriyam/predator-prey/.venv/lib/python3.10/site-packages/urllib3/connection.py", line 218, in _new_conn
    raise NewConnectionError(
urllib3.exceptions.NewConnectionError: <urllib3.connection.HTTPConnection object at 0x14c48d0060b0>: Failed to establish a new connection: [Errno 111] Connection refused

The above exception was the direct cause of the following exception:

Traceback (most recent call last):
  File "/data/gpfs/projects/punim1355/dalmiapriyam/predator-prey/.venv/lib/python3.10/site-packages/requests/adapters.py", line 486, in send
    resp = conn.urlopen(
  File "/data/gpfs/projects/punim1355/dalmiapriyam/predator-prey/.venv/lib/python3.10/site-packages/urllib3/connectionpool.py", line 844, in urlopen
    retries = retries.increment(
  File "/data/gpfs/projects/punim1355/dalmiapriyam/predator-prey/.venv/lib/python3.10/site-packages/urllib3/util/retry.py", line 515, in increment
    raise MaxRetryError(_pool, url, reason) from reason  # type: ignore[arg-type]
urllib3.exceptions.MaxRetryError: HTTPConnectionPool(host='127.0.0.1', port=8265): Max retries exceeded with url: /api/v0/actors?limit=100&timeout=24&detail=False&filter_keys=state&filter_predicates=%3D&filter_values=ALIVE&exclude_driver=True&server_timeout_multiplier=0.8 (Caused by NewConnectionError('<urllib3.connection.HTTPConnection object at 0x14c48d0060b0>: Failed to establish a new connection: [Errno 111] Connection refused'))

During handling of the above exception, another exception occurred:

Traceback (most recent call last):
  File "/data/gpfs/projects/punim1355/dalmiapriyam/predator-prey/.venv/lib/python3.10/site-packages/ray/util/state/api.py", line 192, in _make_http_get_request
    response = self._do_request(
  File "/data/gpfs/projects/punim1355/dalmiapriyam/predator-prey/.venv/lib/python3.10/site-packages/ray/dashboard/modules/dashboard_sdk.py", line 303, in _do_request
    return requests.request(
  File "/data/gpfs/projects/punim1355/dalmiapriyam/predator-prey/.venv/lib/python3.10/site-packages/requests/api.py", line 59, in request
    return session.request(method=method, url=url, **kwargs)
  File "/data/gpfs/projects/punim1355/dalmiapriyam/predator-prey/.venv/lib/python3.10/site-packages/requests/sessions.py", line 589, in request
    resp = self.send(prep, **send_kwargs)
  File "/data/gpfs/projects/punim1355/dalmiapriyam/predator-prey/.venv/lib/python3.10/site-packages/requests/sessions.py", line 703, in send
    r = adapter.send(request, **kwargs)
  File "/data/gpfs/projects/punim1355/dalmiapriyam/predator-prey/.venv/lib/python3.10/site-packages/requests/adapters.py", line 519, in send
    raise ConnectionError(e, request=request)
requests.exceptions.ConnectionError: HTTPConnectionPool(host='127.0.0.1', port=8265): Max retries exceeded with url: /api/v0/actors?limit=100&timeout=24&detail=False&filter_keys=state&filter_predicates=%3D&filter_values=ALIVE&exclude_driver=True&server_timeout_multiplier=0.8 (Caused by NewConnectionError('<urllib3.connection.HTTPConnection object at 0x14c48d0060b0>: Failed to establish a new connection: [Errno 111] Connection refused'))

During handling of the above exception, another exception occurred:

Traceback (most recent call last):
  File "/data/gpfs/projects/punim1355/dalmiapriyam/predator-prey/./test_ray.py", line 25, in <module>
    list_actors(filters=[("state", "=", "ALIVE")])
  File "/data/gpfs/projects/punim1355/dalmiapriyam/predator-prey/.venv/lib/python3.10/site-packages/ray/util/state/api.py", line 817, in list_actors
    return StateApiClient(address=address).list(
  File "/data/gpfs/projects/punim1355/dalmiapriyam/predator-prey/.venv/lib/python3.10/site-packages/ray/util/state/api.py", line 492, in list
    list_api_response = self._make_http_get_request(
  File "/data/gpfs/projects/punim1355/dalmiapriyam/predator-prey/.venv/lib/python3.10/site-packages/ray/util/state/api.py", line 219, in _make_http_get_request
    raise ServerUnavailable(err_str)
ray.util.state.exception.ServerUnavailable: Failed to make request to http://127.0.0.1:8265/api/v0/actors. Failed to connect to API server. Please check the API server log for details. Make sure dependencies are installed with `pip install ray[default]`. Please also check dashboard is available, and included when starting ray cluster, i.e. `ray start --include-dashboard=True --head`. 
Job ID           : 53588017
Cluster          : spartan
User/Project     : dalmiapriyam/punim1355
Nodes            : 1
Wall-clock time  : 00:00:30 / 00:05:00

Displaying overall resources usage from 2023-11-19 17:43:35 to 2023-11-19 17:44:05:

NODE            CPU#        TOT%   ( USR   / SYS   / WIO   / IDLE  ) 

spartan-gpgpu079 : 
                CPU# 1    : -2.0   (  -1.0 /  -1.0 /  -1.0 /  -1.0 ) 

                GPU# 1    : -1.0  


Allocated CPUs            : 1    
  CPUs with usage <25%    : 1    
  CPUs with usage <50%    : 0    
  CPUs with usage >50%    : 0    


Allocated GPUs            : 1    
  GPUs with usage <25%    : 1    
  GPUs with usage <50%    : 0    
  GPUs with usage >50%    : 0    

Memory used (RAM)         : 0.1%  [4MB of 4195MB]

--------------------------------------------

