
Name of the cluster on which the job is executing:	 spartan
Number of CPUs on the allocated node: 	 32
Number of CPUs requested per task: 	 32
Numer of GPUs requested: 	 
Requested GPU count per allocated node: 	 
Requested GPU count per allocated task:	  
The ID of the job allocation:	  54156281
Count of processors available to the job on this node:	  32
Name of the job:	  tst.slurm
List of nodes allocated to the job:	  spartan-gpgpu143
Total number of nodes in the jobâ€™s resource allocation:	  1
Name of the partition in which the job is running:	  deeplearn
Minimum memory required per allocated CPU:	  4000
Requested memory per allocated GPU:	  
Total amount of memory per node that the job needs:	  
List of nodes allocated to the job:	  spartan-gpgpu143
Total number of CPUs allocated:	  1
Maximum number of MPI tasks (thatâ€™s processes): 	 1
Number of tasks requested per core: 	 
Number of tasks requested per GPU: 	 
Number of tasks requested per node:	  1
The scheduling priority (nice value) at the time of job submission. This value is propagated to the spawned processes: 	 0
The MPI rank (or relative process ID) of the current process: 	 0

The directory from which SBATCH was invoked: 	 /data/gpfs/projects/punim1355/dalmiapriyam/predator-prey
The Hostname of the computer from which SBATCH was invoked: 	 spartan-login3.hpc.unimelb.edu.au
The process ID of the corresponding task: 	 94118



 LOADING MODULES: 




 PYTHON SCRIPT OUTPUT: 

2023-12-06 22:48:34,078	WARNING __init__.py:10 -- PG has/have been moved to `rllib_contrib` and will no longer be maintained by the RLlib team. You can still use it/them normally inside RLlib util Ray 2.8, but from Ray 2.9 on, all `rllib_contrib` algorithms will no longer be part of the core repo, and will therefore have to be installed separately with pinned dependencies for e.g. ray[rllib] and other packages! See https://github.com/ray-project/ray/tree/master/rllib_contrib#rllib-contrib for more information on the RLlib contrib effort.
2023-12-06 22:48:37,309	INFO worker.py:1673 -- Started a local Ray instance.
2023-12-06 22:48:37,970	INFO tune.py:220 -- Initializing Ray automatically. For cluster usage or custom Ray initialization, call `ray.init(...)` before `Tuner(...)`.
2023-12-06 22:48:37,972	INFO tune.py:595 -- [output] This will use the new output engine with verbosity 1. To disable the new output and use the legacy output engine, set the environment variable RAY_AIR_NEW_OUTPUT=0. For more information, please see https://github.com/ray-project/ray/issues/36949
[36m(pid=96893)[0m 2023-12-06 22:48:56,446	WARNING __init__.py:10 -- PG has/have been moved to `rllib_contrib` and will no longer be maintained by the RLlib team. You can still use it/them normally inside RLlib util Ray 2.8, but from Ray 2.9 on, all `rllib_contrib` algorithms will no longer be part of the core repo, and will therefore have to be installed separately with pinned dependencies for e.g. ray[rllib] and other packages! See https://github.com/ray-project/ray/tree/master/rllib_contrib#rllib-contrib for more information on the RLlib contrib effort.
[36m(train_algo pid=96891)[0m 2023-12-06 22:48:58,212	WARNING deprecation.py:50 -- DeprecationWarning: `ray.rllib.models.tf.recurrent_net.LSTMWrapper` has been deprecated. This will raise an error in the future!
[36m(train_algo pid=96891)[0m 2023-12-06 22:48:58,212	WARNING deprecation.py:50 -- DeprecationWarning: `ray.rllib.models.torch.visionnet.VisionNetwork` has been deprecated. This will raise an error in the future!
slurmstepd: error: *** JOB 54156281 ON spartan-gpgpu143 CANCELLED AT 2023-12-06T22:48:58 ***
[36m(train_algo pid=96886)[0m 2023-12-06 22:48:58,782	WARNING deprecation.py:50 -- DeprecationWarning: `ray.rllib.models.torch.recurrent_net.RecurrentNetwork` has been deprecated. This will raise an error in the future!
2023-12-06 22:48:58,962	ERROR tune_controller.py:1383 -- Trial task failed for trial train_algo_64c6a_00022
Traceback (most recent call last):
  File "/data/gpfs/projects/punim1355/dalmiapriyam/predator-prey/.venv/lib/python3.10/site-packages/ray/air/execution/_internal/event_manager.py", line 110, in resolve_future
    result = ray.get(future)
  File "/data/gpfs/projects/punim1355/dalmiapriyam/predator-prey/.venv/lib/python3.10/site-packages/ray/_private/auto_init_hook.py", line 24, in auto_init_wrapper
    return fn(*args, **kwargs)
  File "/data/gpfs/projects/punim1355/dalmiapriyam/predator-prey/.venv/lib/python3.10/site-packages/ray/_private/client_mode_hook.py", line 103, in wrapper
    return func(*args, **kwargs)
  File "/data/gpfs/projects/punim1355/dalmiapriyam/predator-prey/.venv/lib/python3.10/site-packages/ray/_private/worker.py", line 2563, in get
    raise value.as_instanceof_cause()
ray.exceptions.RayTaskError(Error): [36mray::ImplicitFunc.train()[39m (pid=96908, ip=172.26.93.143, actor_id=739b8311bb4178ce54d6301b01000000, repr=train_algo)
  File "/data/gpfs/projects/punim1355/dalmiapriyam/predator-prey/.venv/lib/python3.10/site-packages/wandb/sdk/wandb_init.py", line 189, in setup
    self._wl = wandb_setup.setup(settings=setup_settings)
  File "/data/gpfs/projects/punim1355/dalmiapriyam/predator-prey/.venv/lib/python3.10/site-packages/wandb/sdk/wandb_setup.py", line 327, in setup
    ret = _setup(settings=settings)
  File "/data/gpfs/projects/punim1355/dalmiapriyam/predator-prey/.venv/lib/python3.10/site-packages/wandb/sdk/wandb_setup.py", line 320, in _setup
    wl = _WandbSetup(settings=settings)
  File "/data/gpfs/projects/punim1355/dalmiapriyam/predator-prey/.venv/lib/python3.10/site-packages/wandb/sdk/wandb_setup.py", line 303, in __init__
    _WandbSetup._instance = _WandbSetup__WandbSetup(settings=settings, pid=pid)
  File "/data/gpfs/projects/punim1355/dalmiapriyam/predator-prey/.venv/lib/python3.10/site-packages/wandb/sdk/wandb_setup.py", line 114, in __init__
    self._setup()
  File "/data/gpfs/projects/punim1355/dalmiapriyam/predator-prey/.venv/lib/python3.10/site-packages/wandb/sdk/wandb_setup.py", line 250, in _setup
    self._setup_manager()
  File "/data/gpfs/projects/punim1355/dalmiapriyam/predator-prey/.venv/lib/python3.10/site-packages/wandb/sdk/wandb_setup.py", line 277, in _setup_manager
    self._manager = wandb_manager._Manager(settings=self._settings)
  File "/data/gpfs/projects/punim1355/dalmiapriyam/predator-prey/.venv/lib/python3.10/site-packages/wandb/sdk/wandb_manager.py", line 138, in __init__
    self._service.start()
  File "/data/gpfs/projects/punim1355/dalmiapriyam/predator-prey/.venv/lib/python3.10/site-packages/wandb/sdk/service/service.py", line 258, in start
    self._launch_server()
  File "/data/gpfs/projects/punim1355/dalmiapriyam/predator-prey/.venv/lib/python3.10/site-packages/wandb/sdk/service/service.py", line 164, in _launch_server
    with tempfile.TemporaryDirectory() as tmpdir:
  File "/apps/easybuild-2022/easybuild/software/Compiler/GCCcore/11.3.0/Python/3.10.4/lib/python3.10/tempfile.py", line 796, in __init__
    self.name = mkdtemp(suffix, prefix, dir)
  File "/apps/easybuild-2022/easybuild/software/Compiler/GCCcore/11.3.0/Python/3.10.4/lib/python3.10/tempfile.py", line 368, in mkdtemp
    _os.mkdir(file, 0o700)
FileNotFoundError: [Errno 2] No such file or directory: '/tmp/tmpr029_b2o'

The above exception was the direct cause of the following exception:

[36mray::ImplicitFunc.train()[39m (pid=96908, ip=172.26.93.143, actor_id=739b8311bb4178ce54d6301b01000000, repr=train_algo)
  File "/data/gpfs/projects/punim1355/dalmiapriyam/predator-prey/.venv/lib/python3.10/site-packages/ray/tune/trainable/trainable.py", line 342, in train
    raise skipped from exception_cause(skipped)
  File "/data/gpfs/projects/punim1355/dalmiapriyam/predator-prey/.venv/lib/python3.10/site-packages/ray/air/_internal/util.py", line 91, in run
    self._ret = self._target(*self._args, **self._kwargs)
  File "/data/gpfs/projects/punim1355/dalmiapriyam/predator-prey/.venv/lib/python3.10/site-packages/ray/tune/trainable/function_trainable.py", line 115, in <lambda>
    training_func=lambda: self._trainable_func(self.config),
  File "/data/gpfs/projects/punim1355/dalmiapriyam/predator-prey/.venv/lib/python3.10/site-packages/ray/tune/trainable/function_trainable.py", line 332, in _trainable_func
    output = fn()
  File "/data/gpfs/projects/punim1355/dalmiapriyam/predator-prey/./train.py", line 211, in train_algo
    wandb.init(
  File "/data/gpfs/projects/punim1355/dalmiapriyam/predator-prey/.venv/lib/python3.10/site-packages/wandb/sdk/wandb_init.py", line 1204, in init
    raise Error("An unexpected error occurred") from error_seen
wandb.errors.Error: An unexpected error occurred
[36m(train_algo pid=96886)[0m Traceback (most recent call last):
[36m(train_algo pid=96886)[0m   File "/data/gpfs/projects/punim1355/dalmiapriyam/predator-prey/.venv/lib/python3.10/site-packages/wandb/sdk/wandb_init.py", line 1162, in init
[36m(train_algo pid=96886)[0m     wi.setup(kwargs)
[36m(train_algo pid=96886)[0m   File "/data/gpfs/projects/punim1355/dalmiapriyam/predator-prey/.venv/lib/python3.10/site-packages/wandb/sdk/wandb_init.py", line 189, in setup
[36m(train_algo pid=96886)[0m     self._wl = wandb_setup.setup(settings=setup_settings)
[36m(train_algo pid=96886)[0m   File "/data/gpfs/projects/punim1355/dalmiapriyam/predator-prey/.venv/lib/python3.10/site-packages/wandb/sdk/wandb_setup.py", line 327, in setup
[36m(train_algo pid=96886)[0m     ret = _setup(settings=settings)
[36m(train_algo pid=96886)[0m   File "/data/gpfs/projects/punim1355/dalmiapriyam/predator-prey/.venv/lib/python3.10/site-packages/wandb/sdk/wandb_setup.py", line 320, in _setup
[36m(train_algo pid=96886)[0m     wl = _WandbSetup(settings=settings)
[36m(train_algo pid=96886)[0m   File "/data/gpfs/projects/punim1355/dalmiapriyam/predator-prey/.venv/lib/python3.10/site-packages/wandb/sdk/wandb_setup.py", line 303, in __init__
[36m(train_algo pid=96886)[0m     _WandbSetup._instance = _WandbSetup__WandbSetup(settings=settings, pid=pid)
[36m(train_algo pid=96886)[0m   File "/data/gpfs/projects/punim1355/dalmiapriyam/predator-prey/.venv/lib/python3.10/site-packages/wandb/sdk/wandb_setup.py", line 114, in __init__
[36m(train_algo pid=96886)[0m     self._setup()
[36m(train_algo pid=96886)[0m   File "/data/gpfs/projects/punim1355/dalmiapriyam/predator-prey/.venv/lib/python3.10/site-packages/wandb/sdk/wandb_setup.py", line 250, in _setup
[36m(train_algo pid=96886)[0m     self._setup_manager()
[36m(train_algo pid=96886)[0m   File "/data/gpfs/projects/punim1355/dalmiapriyam/predator-prey/.venv/lib/python3.10/site-packages/wandb/sdk/wandb_setup.py", line 277, in _setup_manager
[36m(train_algo pid=96886)[0m     self._manager = wandb_manager._Manager(settings=self._settings)
[36m(train_algo pid=96886)[0m   File "/data/gpfs/projects/punim1355/dalmiapriyam/predator-prey/.venv/lib/python3.10/site-packages/wandb/sdk/wandb_manager.py", line 138, in __init__
[36m(train_algo pid=96886)[0m     self._service.start()
[36m(train_algo pid=96886)[0m   File "/data/gpfs/projects/punim1355/dalmiapriyam/predator-prey/.venv/lib/python3.10/site-packages/wandb/sdk/service/service.py", line 258, in start
[36m(train_algo pid=96886)[0m     self._launch_server()
[36m(train_algo pid=96886)[0m   File "/data/gpfs/projects/punim1355/dalmiapriyam/predator-prey/.venv/lib/python3.10/site-packages/wandb/sdk/service/service.py", line 164, in _launch_server
[36m(train_algo pid=96886)[0m     with tempfile.TemporaryDirectory() as tmpdir:
[36m(train_algo pid=96886)[0m   File "/apps/easybuild-2022/easybuild/software/Compiler/GCCcore/11.3.0/Python/3.10.4/lib/python3.10/tempfile.py", line 796, in __init__
[36m(train_algo pid=96886)[0m     self.name = mkdtemp(suffix, prefix, dir)
[36m(train_algo pid=96886)[0m   File "/apps/easybuild-2022/easybuild/software/Compiler/GCCcore/11.3.0/Python/3.10.4/lib/python3.10/tempfile.py", line 368, in mkdtemp
[36m(train_algo pid=96886)[0m     _os.mkdir(file, 0o700)
[36m(train_algo pid=96886)[0m FileNotFoundError: [Errno 2] No such file or directory: '/tmp/tmpf4w2j8kw'
[36m(train_algo pid=96888)[0m FileNotFoundError: [Errno 2] No such file or directory: '/tmp/tmp__bddiyz'
[36m(train_algo pid=96904)[0m FileNotFoundError: [Errno 2] No such file or directory: '/tmp/tmpfnruniwc'
[36m(train_algo pid=96902)[0m FileNotFoundError: [Errno 2] No such file or directory: '/tmp/tmpnclsfktb'
[36m(train_algo pid=96906)[0m FileNotFoundError: [Errno 2] No such file or directory: '/tmp/tmptznsrbax'
2023-12-06 22:48:58,978	ERROR tune_controller.py:1383 -- Trial task failed for trial train_algo_64c6a_00018
Traceback (most recent call last):
  File "/data/gpfs/projects/punim1355/dalmiapriyam/predator-prey/.venv/lib/python3.10/site-packages/ray/air/execution/_internal/event_manager.py", line 110, in resolve_future
    result = ray.get(future)
  File "/data/gpfs/projects/punim1355/dalmiapriyam/predator-prey/.venv/lib/python3.10/site-packages/ray/_private/auto_init_hook.py", line 24, in auto_init_wrapper
    return fn(*args, **kwargs)
  File "/data/gpfs/projects/punim1355/dalmiapriyam/predator-prey/.venv/lib/python3.10/site-packages/ray/_private/client_mode_hook.py", line 103, in wrapper
    return func(*args, **kwargs)
  File "/data/gpfs/projects/punim1355/dalmiapriyam/predator-prey/.venv/lib/python3.10/site-packages/ray/_private/worker.py", line 2563, in get
    raise value.as_instanceof_cause()
ray.exceptions.RayTaskError(Error): [36mray::ImplicitFunc.train()[39m (pid=96904, ip=172.26.93.143, actor_id=e0a8816b46b1d5de9639ea2c01000000, repr=train_algo)
  File "/data/gpfs/projects/punim1355/dalmiapriyam/predator-prey/.venv/lib/python3.10/site-packages/wandb/sdk/wandb_init.py", line 189, in setup
    self._wl = wandb_setup.setup(settings=setup_settings)
  File "/data/gpfs/projects/punim1355/dalmiapriyam/predator-prey/.venv/lib/python3.10/site-packages/wandb/sdk/wandb_setup.py", line 327, in setup
    ret = _setup(settings=settings)
  File "/data/gpfs/projects/punim1355/dalmiapriyam/predator-prey/.venv/lib/python3.10/site-packages/wandb/sdk/wandb_setup.py", line 320, in _setup
    wl = _WandbSetup(settings=settings)
  File "/data/gpfs/projects/punim1355/dalmiapriyam/predator-prey/.venv/lib/python3.10/site-packages/wandb/sdk/wandb_setup.py", line 303, in __init__
    _WandbSetup._instance = _WandbSetup__WandbSetup(settings=settings, pid=pid)
  File "/data/gpfs/projects/punim1355/dalmiapriyam/predator-prey/.venv/lib/python3.10/site-packages/wandb/sdk/wandb_setup.py", line 114, in __init__
    self._setup()
  File "/data/gpfs/projects/punim1355/dalmiapriyam/predator-prey/.venv/lib/python3.10/site-packages/wandb/sdk/wandb_setup.py", line 250, in _setup
    self._setup_manager()
  File "/data/gpfs/projects/punim1355/dalmiapriyam/predator-prey/.venv/lib/python3.10/site-packages/wandb/sdk/wandb_setup.py", line 277, in _setup_manager
    self._manager = wandb_manager._Manager(settings=self._settings)
  File "/data/gpfs/projects/punim1355/dalmiapriyam/predator-prey/.venv/lib/python3.10/site-packages/wandb/sdk/wandb_manager.py", line 138, in __init__
    self._service.start()
  File "/data/gpfs/projects/punim1355/dalmiapriyam/predator-prey/.venv/lib/python3.10/site-packages/wandb/sdk/service/service.py", line 258, in start
    self._launch_server()
  File "/data/gpfs/projects/punim1355/dalmiapriyam/predator-prey/.venv/lib/python3.10/site-packages/wandb/sdk/service/service.py", line 164, in _launch_server
    with tempfile.TemporaryDirectory() as tmpdir:
  File "/apps/easybuild-2022/easybuild/software/Compiler/GCCcore/11.3.0/Python/3.10.4/lib/python3.10/tempfile.py", line 796, in __init__
    self.name = mkdtemp(suffix, prefix, dir)
  File "/apps/easybuild-2022/easybuild/software/Compiler/GCCcore/11.3.0/Python/3.10.4/lib/python3.10/tempfile.py", line 368, in mkdtemp
    _os.mkdir(file, 0o700)
FileNotFoundError: [Errno 2] No such file or directory: '/tmp/tmpfnruniwc'

The above exception was the direct cause of the following exception:

[36mray::ImplicitFunc.train()[39m (pid=96904, ip=172.26.93.143, actor_id=e0a8816b46b1d5de9639ea2c01000000, repr=train_algo)
  File "/data/gpfs/projects/punim1355/dalmiapriyam/predator-prey/.venv/lib/python3.10/site-packages/ray/tune/trainable/trainable.py", line 342, in train
    raise skipped from exception_cause(skipped)
  File "/data/gpfs/projects/punim1355/dalmiapriyam/predator-prey/.venv/lib/python3.10/site-packages/ray/air/_internal/util.py", line 91, in run
    self._ret = self._target(*self._args, **self._kwargs)
  File "/data/gpfs/projects/punim1355/dalmiapriyam/predator-prey/.venv/lib/python3.10/site-packages/ray/tune/trainable/function_trainable.py", line 115, in <lambda>
    training_func=lambda: self._trainable_func(self.config),
  File "/data/gpfs/projects/punim1355/dalmiapriyam/predator-prey/.venv/lib/python3.10/site-packages/ray/tune/trainable/function_trainable.py", line 332, in _trainable_func
    output = fn()
  File "/data/gpfs/projects/punim1355/dalmiapriyam/predator-prey/./train.py", line 211, in train_algo
    wandb.init(
  File "/data/gpfs/projects/punim1355/dalmiapriyam/predator-prey/.venv/lib/python3.10/site-packages/wandb/sdk/wandb_init.py", line 1204, in init
    raise Error("An unexpected error occurred") from error_seen
wandb.errors.Error: An unexpected error occurred
2023-12-06 22:48:58,988	ERROR tune_controller.py:1383 -- Trial task failed for trial train_algo_64c6a_00025
Traceback (most recent call last):
  File "/data/gpfs/projects/punim1355/dalmiapriyam/predator-prey/.venv/lib/python3.10/site-packages/ray/air/execution/_internal/event_manager.py", line 110, in resolve_future
    result = ray.get(future)
  File "/data/gpfs/projects/punim1355/dalmiapriyam/predator-prey/.venv/lib/python3.10/site-packages/ray/_private/auto_init_hook.py", line 24, in auto_init_wrapper
    return fn(*args, **kwargs)
  File "/data/gpfs/projects/punim1355/dalmiapriyam/predator-prey/.venv/lib/python3.10/site-packages/ray/_private/client_mode_hook.py", line 103, in wrapper
    return func(*args, **kwargs)
  File "/data/gpfs/projects/punim1355/dalmiapriyam/predator-prey/.venv/lib/python3.10/site-packages/ray/_private/worker.py", line 2563, in get
    raise value.as_instanceof_cause()
ray.exceptions.RayTaskError(Error): [36mray::ImplicitFunc.train()[39m (pid=96911, ip=172.26.93.143, actor_id=ccb3dccfc11b2ea92b79e3c701000000, repr=train_algo)
  File "/data/gpfs/projects/punim1355/dalmiapriyam/predator-prey/.venv/lib/python3.10/site-packages/wandb/sdk/wandb_init.py", line 189, in setup
    self._wl = wandb_setup.setup(settings=setup_settings)
  File "/data/gpfs/projects/punim1355/dalmiapriyam/predator-prey/.venv/lib/python3.10/site-packages/wandb/sdk/wandb_setup.py", line 327, in setup
    ret = _setup(settings=settings)
  File "/data/gpfs/projects/punim1355/dalmiapriyam/predator-prey/.venv/lib/python3.10/site-packages/wandb/sdk/wandb_setup.py", line 320, in _setup
    wl = _WandbSetup(settings=settings)
  File "/data/gpfs/projects/punim1355/dalmiapriyam/predator-prey/.venv/lib/python3.10/site-packages/wandb/sdk/wandb_setup.py", line 303, in __init__
    _WandbSetup._instance = _WandbSetup__WandbSetup(settings=settings, pid=pid)
  File "/data/gpfs/projects/punim1355/dalmiapriyam/predator-prey/.venv/lib/python3.10/site-packages/wandb/sdk/wandb_setup.py", line 114, in __init__
    self._setup()
  File "/data/gpfs/projects/punim1355/dalmiapriyam/predator-prey/.venv/lib/python3.10/site-packages/wandb/sdk/wandb_setup.py", line 250, in _setup
    self._setup_manager()
  File "/data/gpfs/projects/punim1355/dalmiapriyam/predator-prey/.venv/lib/python3.10/site-packages/wandb/sdk/wandb_setup.py", line 277, in _setup_manager
    self._manager = wandb_manager._Manager(settings=self._settings)
  File "/data/gpfs/projects/punim1355/dalmiapriyam/predator-prey/.venv/lib/python3.10/site-packages/wandb/sdk/wandb_manager.py", line 138, in __init__
    self._service.start()
  File "/data/gpfs/projects/punim1355/dalmiapriyam/predator-prey/.venv/lib/python3.10/site-packages/wandb/sdk/service/service.py", line 258, in start
    self._launch_server()
  File "/data/gpfs/projects/punim1355/dalmiapriyam/predator-prey/.venv/lib/python3.10/site-packages/wandb/sdk/service/service.py", line 164, in _launch_server
    with tempfile.TemporaryDirectory() as tmpdir:
  File "/apps/easybuild-2022/easybuild/software/Compiler/GCCcore/11.3.0/Python/3.10.4/lib/python3.10/tempfile.py", line 796, in __init__
    self.name = mkdtemp(suffix, prefix, dir)
  File "/apps/easybuild-2022/easybuild/software/Compiler/GCCcore/11.3.0/Python/3.10.4/lib/python3.10/tempfile.py", line 368, in mkdtemp
    _os.mkdir(file, 0o700)
FileNotFoundError: [Errno 2] No such file or directory: '/tmp/tmp388iuwcv'

The above exception was the direct cause of the following exception:

[36mray::ImplicitFunc.train()[39m (pid=96911, ip=172.26.93.143, actor_id=ccb3dccfc11b2ea92b79e3c701000000, repr=train_algo)
  File "/data/gpfs/projects/punim1355/dalmiapriyam/predator-prey/.venv/lib/python3.10/site-packages/ray/tune/trainable/trainable.py", line 342, in train
    raise skipped from exception_cause(skipped)
  File "/data/gpfs/projects/punim1355/dalmiapriyam/predator-prey/.venv/lib/python3.10/site-packages/ray/air/_internal/util.py", line 91, in run
    self._ret = self._target(*self._args, **self._kwargs)
  File "/data/gpfs/projects/punim1355/dalmiapriyam/predator-prey/.venv/lib/python3.10/site-packages/ray/tune/trainable/function_trainable.py", line 115, in <lambda>
    training_func=lambda: self._trainable_func(self.config),
  File "/data/gpfs/projects/punim1355/dalmiapriyam/predator-prey/.venv/lib/python3.10/site-packages/ray/tune/trainable/function_trainable.py", line 332, in _trainable_func
    output = fn()
  File "/data/gpfs/projects/punim1355/dalmiapriyam/predator-prey/./train.py", line 211, in train_algo
    wandb.init(
  File "/data/gpfs/projects/punim1355/dalmiapriyam/predator-prey/.venv/lib/python3.10/site-packages/wandb/sdk/wandb_init.py", line 1204, in init
    raise Error("An unexpected error occurred") from error_seen
wandb.errors.Error: An unexpected error occurred
2023-12-06 22:48:58,996	ERROR tune_controller.py:1383 -- Trial task failed for trial train_algo_64c6a_00010
Traceback (most recent call last):
  File "/data/gpfs/projects/punim1355/dalmiapriyam/predator-prey/.venv/lib/python3.10/site-packages/ray/air/execution/_internal/event_manager.py", line 110, in resolve_future
    result = ray.get(future)
  File "/data/gpfs/projects/punim1355/dalmiapriyam/predator-prey/.venv/lib/python3.10/site-packages/ray/_private/auto_init_hook.py", line 24, in auto_init_wrapper
    return fn(*args, **kwargs)
  File "/data/gpfs/projects/punim1355/dalmiapriyam/predator-prey/.venv/lib/python3.10/site-packages/ray/_private/client_mode_hook.py", line 103, in wrapper
    return func(*args, **kwargs)
  File "/data/gpfs/projects/punim1355/dalmiapriyam/predator-prey/.venv/lib/python3.10/site-packages/ray/_private/worker.py", line 2563, in get
    raise value.as_instanceof_cause()
ray.exceptions.RayTaskError(Error): [36mray::ImplicitFunc.train()[39m (pid=96896, ip=172.26.93.143, actor_id=b31524d4cd33b019e954d86c01000000, repr=train_algo)
  File "/data/gpfs/projects/punim1355/dalmiapriyam/predator-prey/.venv/lib/python3.10/site-packages/wandb/sdk/wandb_init.py", line 189, in setup
    self._wl = wandb_setup.setup(settings=setup_settings)
  File "/data/gpfs/projects/punim1355/dalmiapriyam/predator-prey/.venv/lib/python3.10/site-packages/wandb/sdk/wandb_setup.py", line 327, in setup
    ret = _setup(settings=settings)
  File "/data/gpfs/projects/punim1355/dalmiapriyam/predator-prey/.venv/lib/python3.10/site-packages/wandb/sdk/wandb_setup.py", line 320, in _setup
    wl = _WandbSetup(settings=settings)
  File "/data/gpfs/projects/punim1355/dalmiapriyam/predator-prey/.venv/lib/python3.10/site-packages/wandb/sdk/wandb_setup.py", line 303, in __init__
    _WandbSetup._instance = _WandbSetup__WandbSetup(settings=settings, pid=pid)
  File "/data/gpfs/projects/punim1355/dalmiapriyam/predator-prey/.venv/lib/python3.10/site-packages/wandb/sdk/wandb_setup.py", line 114, in __init__
    self._setup()
  File "/data/gpfs/projects/punim1355/dalmiapriyam/predator-prey/.venv/lib/python3.10/site-packages/wandb/sdk/wandb_setup.py", line 250, in _setup
    self._setup_manager()
  File "/data/gpfs/projects/punim1355/dalmiapriyam/predator-prey/.venv/lib/python3.10/site-packages/wandb/sdk/wandb_setup.py", line 277, in _setup_manager
    self._manager = wandb_manager._Manager(settings=self._settings)
  File "/data/gpfs/projects/punim1355/dalmiapriyam/predator-prey/.venv/lib/python3.10/site-packages/wandb/sdk/wandb_manager.py", line 138, in __init__
    self._service.start()
  File "/data/gpfs/projects/punim1355/dalmiapriyam/predator-prey/.venv/lib/python3.10/site-packages/wandb/sdk/service/service.py", line 258, in start
    self._launch_server()
  File "/data/gpfs/projects/punim1355/dalmiapriyam/predator-prey/.venv/lib/python3.10/site-packages/wandb/sdk/service/service.py", line 164, in _launch_server
    with tempfile.TemporaryDirectory() as tmpdir:
  File "/apps/easybuild-2022/easybuild/software/Compiler/GCCcore/11.3.0/Python/3.10.4/lib/python3.10/tempfile.py", line 796, in __init__
    self.name = mkdtemp(suffix, prefix, dir)
  File "/apps/easybuild-2022/easybuild/software/Compiler/GCCcore/11.3.0/Python/3.10.4/lib/python3.10/tempfile.py", line 368, in mkdtemp
    _os.mkdir(file, 0o700)
FileNotFoundError: [Errno 2] No such file or directory: '/tmp/tmpxoye6w9g'

The above exception was the direct cause of the following exception:

[36mray::ImplicitFunc.train()[39m (pid=96896, ip=172.26.93.143, actor_id=b31524d4cd33b019e954d86c01000000, repr=train_algo)
  File "/data/gpfs/projects/punim1355/dalmiapriyam/predator-prey/.venv/lib/python3.10/site-packages/ray/tune/trainable/trainable.py", line 342, in train
    raise skipped from exception_cause(skipped)
  File "/data/gpfs/projects/punim1355/dalmiapriyam/predator-prey/.venv/lib/python3.10/site-packages/ray/air/_internal/util.py", line 91, in run
    self._ret = self._target(*self._args, **self._kwargs)
  File "/data/gpfs/projects/punim1355/dalmiapriyam/predator-prey/.venv/lib/python3.10/site-packages/ray/tune/trainable/function_trainable.py", line 115, in <lambda>
    training_func=lambda: self._trainable_func(self.config),
  File "/data/gpfs/projects/punim1355/dalmiapriyam/predator-prey/.venv/lib/python3.10/site-packages/ray/tune/trainable/function_trainable.py", line 332, in _trainable_func
    output = fn()
  File "/data/gpfs/projects/punim1355/dalmiapriyam/predator-prey/./train.py", line 211, in train_algo
    wandb.init(
  File "/data/gpfs/projects/punim1355/dalmiapriyam/predator-prey/.venv/lib/python3.10/site-packages/wandb/sdk/wandb_init.py", line 1204, in init
    raise Error("An unexpected error occurred") from error_seen
wandb.errors.Error: An unexpected error occurred
2023-12-06 22:48:59,003	ERROR tune_controller.py:1383 -- Trial task failed for trial train_algo_64c6a_00024
Traceback (most recent call last):
  File "/data/gpfs/projects/punim1355/dalmiapriyam/predator-prey/.venv/lib/python3.10/site-packages/ray/air/execution/_internal/event_manager.py", line 110, in resolve_future
    result = ray.get(future)
  File "/data/gpfs/projects/punim1355/dalmiapriyam/predator-prey/.venv/lib/python3.10/site-packages/ray/_private/auto_init_hook.py", line 24, in auto_init_wrapper
    return fn(*args, **kwargs)
  File "/data/gpfs/projects/punim1355/dalmiapriyam/predator-prey/.venv/lib/python3.10/site-packages/ray/_private/client_mode_hook.py", line 103, in wrapper
    return func(*args, **kwargs)
  File "/data/gpfs/projects/punim1355/dalmiapriyam/predator-prey/.venv/lib/python3.10/site-packages/ray/_private/worker.py", line 2563, in get
    raise value.as_instanceof_cause()
ray.exceptions.RayTaskError(Error): [36mray::ImplicitFunc.train()[39m (pid=96910, ip=172.26.93.143, actor_id=f02acc131fb63b989b5cc36301000000, repr=train_algo)
  File "/data/gpfs/projects/punim1355/dalmiapriyam/predator-prey/.venv/lib/python3.10/site-packages/wandb/sdk/wandb_init.py", line 189, in setup
    self._wl = wandb_setup.setup(settings=setup_settings)
  File "/data/gpfs/projects/punim1355/dalmiapriyam/predator-prey/.venv/lib/python3.10/site-packages/wandb/sdk/wandb_setup.py", line 327, in setup
    ret = _setup(settings=settings)
  File "/data/gpfs/projects/punim1355/dalmiapriyam/predator-prey/.venv/lib/python3.10/site-packages/wandb/sdk/wandb_setup.py", line 320, in _setup
    wl = _WandbSetup(settings=settings)
  File "/data/gpfs/projects/punim1355/dalmiapriyam/predator-prey/.venv/lib/python3.10/site-packages/wandb/sdk/wandb_setup.py", line 303, in __init__
    _WandbSetup._instance = _WandbSetup__WandbSetup(settings=settings, pid=pid)
  File "/data/gpfs/projects/punim1355/dalmiapriyam/predator-prey/.venv/lib/python3.10/site-packages/wandb/sdk/wandb_setup.py", line 114, in __init__
    self._setup()
  File "/data/gpfs/projects/punim1355/dalmiapriyam/predator-prey/.venv/lib/python3.10/site-packages/wandb/sdk/wandb_setup.py", line 250, in _setup
    self._setup_manager()
  File "/data/gpfs/projects/punim1355/dalmiapriyam/predator-prey/.venv/lib/python3.10/site-packages/wandb/sdk/wandb_setup.py", line 277, in _setup_manager
    self._manager = wandb_manager._Manager(settings=self._settings)
  File "/data/gpfs/projects/punim1355/dalmiapriyam/predator-prey/.venv/lib/python3.10/site-packages/wandb/sdk/wandb_manager.py", line 138, in __init__
    self._service.start()
  File "/data/gpfs/projects/punim1355/dalmiapriyam/predator-prey/.venv/lib/python3.10/site-packages/wandb/sdk/service/service.py", line 258, in start
    self._launch_server()
  File "/data/gpfs/projects/punim1355/dalmiapriyam/predator-prey/.venv/lib/python3.10/site-packages/wandb/sdk/service/service.py", line 164, in _launch_server
    with tempfile.TemporaryDirectory() as tmpdir:
  File "/apps/easybuild-2022/easybuild/software/Compiler/GCCcore/11.3.0/Python/3.10.4/lib/python3.10/tempfile.py", line 796, in __init__
    self.name = mkdtemp(suffix, prefix, dir)
  File "/apps/easybuild-2022/easybuild/software/Compiler/GCCcore/11.3.0/Python/3.10.4/lib/python3.10/tempfile.py", line 368, in mkdtemp
    _os.mkdir(file, 0o700)
FileNotFoundError: [Errno 2] No such file or directory: '/tmp/tmp1ruwk2jo'

The above exception was the direct cause of the following exception:

[36mray::ImplicitFunc.train()[39m (pid=96910, ip=172.26.93.143, actor_id=f02acc131fb63b989b5cc36301000000, repr=train_algo)
  File "/data/gpfs/projects/punim1355/dalmiapriyam/predator-prey/.venv/lib/python3.10/site-packages/ray/tune/trainable/trainable.py", line 342, in train
    raise skipped from exception_cause(skipped)
  File "/data/gpfs/projects/punim1355/dalmiapriyam/predator-prey/.venv/lib/python3.10/site-packages/ray/air/_internal/util.py", line 91, in run
    self._ret = self._target(*self._args, **self._kwargs)
  File "/data/gpfs/projects/punim1355/dalmiapriyam/predator-prey/.venv/lib/python3.10/site-packages/ray/tune/trainable/function_trainable.py", line 115, in <lambda>
    training_func=lambda: self._trainable_func(self.config),
  File "/data/gpfs/projects/punim1355/dalmiapriyam/predator-prey/.venv/lib/python3.10/site-packages/ray/tune/trainable/function_trainable.py", line 332, in _trainable_func
    output = fn()
  File "/data/gpfs/projects/punim1355/dalmiapriyam/predator-prey/./train.py", line 211, in train_algo
    wandb.init(
  File "/data/gpfs/projects/punim1355/dalmiapriyam/predator-prey/.venv/lib/python3.10/site-packages/wandb/sdk/wandb_init.py", line 1204, in init
    raise Error("An unexpected error occurred") from error_seen
wandb.errors.Error: An unexpected error occurred
2023-12-06 22:48:59,010	ERROR tune_controller.py:1383 -- Trial task failed for trial train_algo_64c6a_00020
Traceback (most recent call last):
  File "/data/gpfs/projects/punim1355/dalmiapriyam/predator-prey/.venv/lib/python3.10/site-packages/ray/air/execution/_internal/event_manager.py", line 110, in resolve_future
    result = ray.get(future)
  File "/data/gpfs/projects/punim1355/dalmiapriyam/predator-prey/.venv/lib/python3.10/site-packages/ray/_private/auto_init_hook.py", line 24, in auto_init_wrapper
    return fn(*args, **kwargs)
  File "/data/gpfs/projects/punim1355/dalmiapriyam/predator-prey/.venv/lib/python3.10/site-packages/ray/_private/client_mode_hook.py", line 103, in wrapper
    return func(*args, **kwargs)
  File "/data/gpfs/projects/punim1355/dalmiapriyam/predator-prey/.venv/lib/python3.10/site-packages/ray/_private/worker.py", line 2563, in get
    raise value.as_instanceof_cause()
ray.exceptions.RayTaskError(Error): [36mray::ImplicitFunc.train()[39m (pid=96906, ip=172.26.93.143, actor_id=1ae917c16ada7507cf8e2ec701000000, repr=train_algo)
  File "/data/gpfs/projects/punim1355/dalmiapriyam/predator-prey/.venv/lib/python3.10/site-packages/wandb/sdk/wandb_init.py", line 189, in setup
    self._wl = wandb_setup.setup(settings=setup_settings)
  File "/data/gpfs/projects/punim1355/dalmiapriyam/predator-prey/.venv/lib/python3.10/site-packages/wandb/sdk/wandb_setup.py", line 327, in setup
    ret = _setup(settings=settings)
  File "/data/gpfs/projects/punim1355/dalmiapriyam/predator-prey/.venv/lib/python3.10/site-packages/wandb/sdk/wandb_setup.py", line 320, in _setup
    wl = _WandbSetup(settings=settings)
  File "/data/gpfs/projects/punim1355/dalmiapriyam/predator-prey/.venv/lib/python3.10/site-packages/wandb/sdk/wandb_setup.py", line 303, in __init__
    _WandbSetup._instance = _WandbSetup__WandbSetup(settings=settings, pid=pid)
  File "/data/gpfs/projects/punim1355/dalmiapriyam/predator-prey/.venv/lib/python3.10/site-packages/wandb/sdk/wandb_setup.py", line 114, in __init__
    self._setup()
  File "/data/gpfs/projects/punim1355/dalmiapriyam/predator-prey/.venv/lib/python3.10/site-packages/wandb/sdk/wandb_setup.py", line 250, in _setup
    self._setup_manager()
  File "/data/gpfs/projects/punim1355/dalmiapriyam/predator-prey/.venv/lib/python3.10/site-packages/wandb/sdk/wandb_setup.py", line 277, in _setup_manager
    self._manager = wandb_manager._Manager(settings=self._settings)
  File "/data/gpfs/projects/punim1355/dalmiapriyam/predator-prey/.venv/lib/python3.10/site-packages/wandb/sdk/wandb_manager.py", line 138, in __init__
    self._service.start()
  File "/data/gpfs/projects/punim1355/dalmiapriyam/predator-prey/.venv/lib/python3.10/site-packages/wandb/sdk/service/service.py", line 258, in start
    self._launch_server()
  File "/data/gpfs/projects/punim1355/dalmiapriyam/predator-prey/.venv/lib/python3.10/site-packages/wandb/sdk/service/service.py", line 164, in _launch_server
    with tempfile.TemporaryDirectory() as tmpdir:
  File "/apps/easybuild-2022/easybuild/software/Compiler/GCCcore/11.3.0/Python/3.10.4/lib/python3.10/tempfile.py", line 796, in __init__
    self.name = mkdtemp(suffix, prefix, dir)
  File "/apps/easybuild-2022/easybuild/software/Compiler/GCCcore/11.3.0/Python/3.10.4/lib/python3.10/tempfile.py", line 368, in mkdtemp
    _os.mkdir(file, 0o700)
FileNotFoundError: [Errno 2] No such file or directory: '/tmp/tmptznsrbax'

The above exception was the direct cause of the following exception:

[36mray::ImplicitFunc.train()[39m (pid=96906, ip=172.26.93.143, actor_id=1ae917c16ada7507cf8e2ec701000000, repr=train_algo)
  File "/data/gpfs/projects/punim1355/dalmiapriyam/predator-prey/.venv/lib/python3.10/site-packages/ray/tune/trainable/trainable.py", line 342, in train
    raise skipped from exception_cause(skipped)
  File "/data/gpfs/projects/punim1355/dalmiapriyam/predator-prey/.venv/lib/python3.10/site-packages/ray/air/_internal/util.py", line 91, in run
    self._ret = self._target(*self._args, **self._kwargs)
  File "/data/gpfs/projects/punim1355/dalmiapriyam/predator-prey/.venv/lib/python3.10/site-packages/ray/tune/trainable/function_trainable.py", line 115, in <lambda>
    training_func=lambda: self._trainable_func(self.config),
  File "/data/gpfs/projects/punim1355/dalmiapriyam/predator-prey/.venv/lib/python3.10/site-packages/ray/tune/trainable/function_trainable.py", line 332, in _trainable_func
    output = fn()
  File "/data/gpfs/projects/punim1355/dalmiapriyam/predator-prey/./train.py", line 211, in train_algo
    wandb.init(
  File "/data/gpfs/projects/punim1355/dalmiapriyam/predator-prey/.venv/lib/python3.10/site-packages/wandb/sdk/wandb_init.py", line 1204, in init
    raise Error("An unexpected error occurred") from error_seen
wandb.errors.Error: An unexpected error occurred
2023-12-06 22:48:59,017	ERROR tune_controller.py:1383 -- Trial task failed for trial train_algo_64c6a_00004
Traceback (most recent call last):
  File "/data/gpfs/projects/punim1355/dalmiapriyam/predator-prey/.venv/lib/python3.10/site-packages/ray/air/execution/_internal/event_manager.py", line 110, in resolve_future
    result = ray.get(future)
  File "/data/gpfs/projects/punim1355/dalmiapriyam/predator-prey/.venv/lib/python3.10/site-packages/ray/_private/auto_init_hook.py", line 24, in auto_init_wrapper
    return fn(*args, **kwargs)
  File "/data/gpfs/projects/punim1355/dalmiapriyam/predator-prey/.venv/lib/python3.10/site-packages/ray/_private/client_mode_hook.py", line 103, in wrapper
    return func(*args, **kwargs)
  File "/data/gpfs/projects/punim1355/dalmiapriyam/predator-prey/.venv/lib/python3.10/site-packages/ray/_private/worker.py", line 2563, in get
    raise value.as_instanceof_cause()
ray.exceptions.RayTaskError(Error): [36mray::ImplicitFunc.train()[39m (pid=96890, ip=172.26.93.143, actor_id=74ced8953d11b88e06dd103a01000000, repr=train_algo)
  File "/data/gpfs/projects/punim1355/dalmiapriyam/predator-prey/.venv/lib/python3.10/site-packages/wandb/sdk/wandb_init.py", line 189, in setup
    self._wl = wandb_setup.setup(settings=setup_settings)
  File "/data/gpfs/projects/punim1355/dalmiapriyam/predator-prey/.venv/lib/python3.10/site-packages/wandb/sdk/wandb_setup.py", line 327, in setup
    ret = _setup(settings=settings)
  File "/data/gpfs/projects/punim1355/dalmiapriyam/predator-prey/.venv/lib/python3.10/site-packages/wandb/sdk/wandb_setup.py", line 320, in _setup
    wl = _WandbSetup(settings=settings)
  File "/data/gpfs/projects/punim1355/dalmiapriyam/predator-prey/.venv/lib/python3.10/site-packages/wandb/sdk/wandb_setup.py", line 303, in __init__
    _WandbSetup._instance = _WandbSetup__WandbSetup(settings=settings, pid=pid)
  File "/data/gpfs/projects/punim1355/dalmiapriyam/predator-prey/.venv/lib/python3.10/site-packages/wandb/sdk/wandb_setup.py", line 114, in __init__
    self._setup()
  File "/data/gpfs/projects/punim1355/dalmiapriyam/predator-prey/.venv/lib/python3.10/site-packages/wandb/sdk/wandb_setup.py", line 250, in _setup
    self._setup_manager()
  File "/data/gpfs/projects/punim1355/dalmiapriyam/predator-prey/.venv/lib/python3.10/site-packages/wandb/sdk/wandb_setup.py", line 277, in _setup_manager
    self._manager = wandb_manager._Manager(settings=self._settings)
  File "/data/gpfs/projects/punim1355/dalmiapriyam/predator-prey/.venv/lib/python3.10/site-packages/wandb/sdk/wandb_manager.py", line 138, in __init__
    self._service.start()
  File "/data/gpfs/projects/punim1355/dalmiapriyam/predator-prey/.venv/lib/python3.10/site-packages/wandb/sdk/service/service.py", line 258, in start
    self._launch_server()
  File "/data/gpfs/projects/punim1355/dalmiapriyam/predator-prey/.venv/lib/python3.10/site-packages/wandb/sdk/service/service.py", line 164, in _launch_server
    with tempfile.TemporaryDirectory() as tmpdir:
  File "/apps/easybuild-2022/easybuild/software/Compiler/GCCcore/11.3.0/Python/3.10.4/lib/python3.10/tempfile.py", line 796, in __init__
    self.name = mkdtemp(suffix, prefix, dir)
  File "/apps/easybuild-2022/easybuild/software/Compiler/GCCcore/11.3.0/Python/3.10.4/lib/python3.10/tempfile.py", line 368, in mkdtemp
    _os.mkdir(file, 0o700)
FileNotFoundError: [Errno 2] No such file or directory: '/tmp/tmp1bnmdtfx'

The above exception was the direct cause of the following exception:

[36mray::ImplicitFunc.train()[39m (pid=96890, ip=172.26.93.143, actor_id=74ced8953d11b88e06dd103a01000000, repr=train_algo)
  File "/data/gpfs/projects/punim1355/dalmiapriyam/predator-prey/.venv/lib/python3.10/site-packages/ray/tune/trainable/trainable.py", line 342, in train
    raise skipped from exception_cause(skipped)
  File "/data/gpfs/projects/punim1355/dalmiapriyam/predator-prey/.venv/lib/python3.10/site-packages/ray/air/_internal/util.py", line 91, in run
    self._ret = self._target(*self._args, **self._kwargs)
  File "/data/gpfs/projects/punim1355/dalmiapriyam/predator-prey/.venv/lib/python3.10/site-packages/ray/tune/trainable/function_trainable.py", line 115, in <lambda>
    training_func=lambda: self._trainable_func(self.config),
  File "/data/gpfs/projects/punim1355/dalmiapriyam/predator-prey/.venv/lib/python3.10/site-packages/ray/tune/trainable/function_trainable.py", line 332, in _trainable_func
    output = fn()
  File "/data/gpfs/projects/punim1355/dalmiapriyam/predator-prey/./train.py", line 211, in train_algo
    wandb.init(
  File "/data/gpfs/projects/punim1355/dalmiapriyam/predator-prey/.venv/lib/python3.10/site-packages/wandb/sdk/wandb_init.py", line 1204, in init
    raise Error("An unexpected error occurred") from error_seen
wandb.errors.Error: An unexpected error occurred
2023-12-06 22:48:59,025	ERROR tune_controller.py:1383 -- Trial task failed for trial train_algo_64c6a_00006
Traceback (most recent call last):
  File "/data/gpfs/projects/punim1355/dalmiapriyam/predator-prey/.venv/lib/python3.10/site-packages/ray/air/execution/_internal/event_manager.py", line 110, in resolve_future
    result = ray.get(future)
  File "/data/gpfs/projects/punim1355/dalmiapriyam/predator-prey/.venv/lib/python3.10/site-packages/ray/_private/auto_init_hook.py", line 24, in auto_init_wrapper
    return fn(*args, **kwargs)
  File "/data/gpfs/projects/punim1355/dalmiapriyam/predator-prey/.venv/lib/python3.10/site-packages/ray/_private/client_mode_hook.py", line 103, in wrapper
    return func(*args, **kwargs)
  File "/data/gpfs/projects/punim1355/dalmiapriyam/predator-prey/.venv/lib/python3.10/site-packages/ray/_private/worker.py", line 2563, in get
    raise value.as_instanceof_cause()
ray.exceptions.RayTaskError(Error): [36mray::ImplicitFunc.train()[39m (pid=96892, ip=172.26.93.143, actor_id=da741545d762ba430d07b4b301000000, repr=train_algo)
  File "/data/gpfs/projects/punim1355/dalmiapriyam/predator-prey/.venv/lib/python3.10/site-packages/wandb/sdk/wandb_init.py", line 189, in setup
    self._wl = wandb_setup.setup(settings=setup_settings)
  File "/data/gpfs/projects/punim1355/dalmiapriyam/predator-prey/.venv/lib/python3.10/site-packages/wandb/sdk/wandb_setup.py", line 327, in setup
    ret = _setup(settings=settings)
  File "/data/gpfs/projects/punim1355/dalmiapriyam/predator-prey/.venv/lib/python3.10/site-packages/wandb/sdk/wandb_setup.py", line 320, in _setup
    wl = _WandbSetup(settings=settings)
  File "/data/gpfs/projects/punim1355/dalmiapriyam/predator-prey/.venv/lib/python3.10/site-packages/wandb/sdk/wandb_setup.py", line 303, in __init__
    _WandbSetup._instance = _WandbSetup__WandbSetup(settings=settings, pid=pid)
  File "/data/gpfs/projects/punim1355/dalmiapriyam/predator-prey/.venv/lib/python3.10/site-packages/wandb/sdk/wandb_setup.py", line 114, in __init__
    self._setup()
  File "/data/gpfs/projects/punim1355/dalmiapriyam/predator-prey/.venv/lib/python3.10/site-packages/wandb/sdk/wandb_setup.py", line 250, in _setup
    self._setup_manager()
  File "/data/gpfs/projects/punim1355/dalmiapriyam/predator-prey/.venv/lib/python3.10/site-packages/wandb/sdk/wandb_setup.py", line 277, in _setup_manager
    self._manager = wandb_manager._Manager(settings=self._settings)
  File "/data/gpfs/projects/punim1355/dalmiapriyam/predator-prey/.venv/lib/python3.10/site-packages/wandb/sdk/wandb_manager.py", line 138, in __init__
    self._service.start()
  File "/data/gpfs/projects/punim1355/dalmiapriyam/predator-prey/.venv/lib/python3.10/site-packages/wandb/sdk/service/service.py", line 258, in start
    self._launch_server()
  File "/data/gpfs/projects/punim1355/dalmiapriyam/predator-prey/.venv/lib/python3.10/site-packages/wandb/sdk/service/service.py", line 164, in _launch_server
    with tempfile.TemporaryDirectory() as tmpdir:
  File "/apps/easybuild-2022/easybuild/software/Compiler/GCCcore/11.3.0/Python/3.10.4/lib/python3.10/tempfile.py", line 796, in __init__
    self.name = mkdtemp(suffix, prefix, dir)
  File "/apps/easybuild-2022/easybuild/software/Compiler/GCCcore/11.3.0/Python/3.10.4/lib/python3.10/tempfile.py", line 368, in mkdtemp
    _os.mkdir(file, 0o700)
FileNotFoundError: [Errno 2] No such file or directory: '/tmp/tmp6ipu97ls'

The above exception was the direct cause of the following exception:

[36mray::ImplicitFunc.train()[39m (pid=96892, ip=172.26.93.143, actor_id=da741545d762ba430d07b4b301000000, repr=train_algo)
  File "/data/gpfs/projects/punim1355/dalmiapriyam/predator-prey/.venv/lib/python3.10/site-packages/ray/tune/trainable/trainable.py", line 342, in train
    raise skipped from exception_cause(skipped)
  File "/data/gpfs/projects/punim1355/dalmiapriyam/predator-prey/.venv/lib/python3.10/site-packages/ray/air/_internal/util.py", line 91, in run
    self._ret = self._target(*self._args, **self._kwargs)
  File "/data/gpfs/projects/punim1355/dalmiapriyam/predator-prey/.venv/lib/python3.10/site-packages/ray/tune/trainable/function_trainable.py", line 115, in <lambda>
    training_func=lambda: self._trainable_func(self.config),
  File "/data/gpfs/projects/punim1355/dalmiapriyam/predator-prey/.venv/lib/python3.10/site-packages/ray/tune/trainable/function_trainable.py", line 332, in _trainable_func
    output = fn()
  File "/data/gpfs/projects/punim1355/dalmiapriyam/predator-prey/./train.py", line 211, in train_algo
    wandb.init(
  File "/data/gpfs/projects/punim1355/dalmiapriyam/predator-prey/.venv/lib/python3.10/site-packages/wandb/sdk/wandb_init.py", line 1204, in init
    raise Error("An unexpected error occurred") from error_seen
wandb.errors.Error: An unexpected error occurred
2023-12-06 22:48:59,034	ERROR tune_controller.py:1383 -- Trial task failed for trial train_algo_64c6a_00019
Traceback (most recent call last):
  File "/data/gpfs/projects/punim1355/dalmiapriyam/predator-prey/.venv/lib/python3.10/site-packages/ray/air/execution/_internal/event_manager.py", line 110, in resolve_future
    result = ray.get(future)
  File "/data/gpfs/projects/punim1355/dalmiapriyam/predator-prey/.venv/lib/python3.10/site-packages/ray/_private/auto_init_hook.py", line 24, in auto_init_wrapper
    return fn(*args, **kwargs)
  File "/data/gpfs/projects/punim1355/dalmiapriyam/predator-prey/.venv/lib/python3.10/site-packages/ray/_private/client_mode_hook.py", line 103, in wrapper
    return func(*args, **kwargs)
  File "/data/gpfs/projects/punim1355/dalmiapriyam/predator-prey/.venv/lib/python3.10/site-packages/ray/_private/worker.py", line 2563, in get
    raise value.as_instanceof_cause()
ray.exceptions.RayTaskError(Error): [36mray::ImplicitFunc.train()[39m (pid=96905, ip=172.26.93.143, actor_id=6b924c8990c1ccfa3f39af5e01000000, repr=train_algo)
  File "/data/gpfs/projects/punim1355/dalmiapriyam/predator-prey/.venv/lib/python3.10/site-packages/wandb/sdk/wandb_init.py", line 189, in setup
    self._wl = wandb_setup.setup(settings=setup_settings)
  File "/data/gpfs/projects/punim1355/dalmiapriyam/predator-prey/.venv/lib/python3.10/site-packages/wandb/sdk/wandb_setup.py", line 327, in setup
    ret = _setup(settings=settings)
  File "/data/gpfs/projects/punim1355/dalmiapriyam/predator-prey/.venv/lib/python3.10/site-packages/wandb/sdk/wandb_setup.py", line 320, in _setup
    wl = _WandbSetup(settings=settings)
  File "/data/gpfs/projects/punim1355/dalmiapriyam/predator-prey/.venv/lib/python3.10/site-packages/wandb/sdk/wandb_setup.py", line 303, in __init__
    _WandbSetup._instance = _WandbSetup__WandbSetup(settings=settings, pid=pid)
  File "/data/gpfs/projects/punim1355/dalmiapriyam/predator-prey/.venv/lib/python3.10/site-packages/wandb/sdk/wandb_setup.py", line 114, in __init__
    self._setup()
  File "/data/gpfs/projects/punim1355/dalmiapriyam/predator-prey/.venv/lib/python3.10/site-packages/wandb/sdk/wandb_setup.py", line 250, in _setup
    self._setup_manager()
  File "/data/gpfs/projects/punim1355/dalmiapriyam/predator-prey/.venv/lib/python3.10/site-packages/wandb/sdk/wandb_setup.py", line 277, in _setup_manager
    self._manager = wandb_manager._Manager(settings=self._settings)
  File "/data/gpfs/projects/punim1355/dalmiapriyam/predator-prey/.venv/lib/python3.10/site-packages/wandb/sdk/wandb_manager.py", line 138, in __init__
    self._service.start()
  File "/data/gpfs/projects/punim1355/dalmiapriyam/predator-prey/.venv/lib/python3.10/site-packages/wandb/sdk/service/service.py", line 258, in start
    self._launch_server()
  File "/data/gpfs/projects/punim1355/dalmiapriyam/predator-prey/.venv/lib/python3.10/site-packages/wandb/sdk/service/service.py", line 164, in _launch_server
    with tempfile.TemporaryDirectory() as tmpdir:
  File "/apps/easybuild-2022/easybuild/software/Compiler/GCCcore/11.3.0/Python/3.10.4/lib/python3.10/tempfile.py", line 796, in __init__
    self.name = mkdtemp(suffix, prefix, dir)
  File "/apps/easybuild-2022/easybuild/software/Compiler/GCCcore/11.3.0/Python/3.10.4/lib/python3.10/tempfile.py", line 368, in mkdtemp
    _os.mkdir(file, 0o700)
FileNotFoundError: [Errno 2] No such file or directory: '/tmp/tmp74m4dq2h'

The above exception was the direct cause of the following exception:

[36mray::ImplicitFunc.train()[39m (pid=96905, ip=172.26.93.143, actor_id=6b924c8990c1ccfa3f39af5e01000000, repr=train_algo)
  File "/data/gpfs/projects/punim1355/dalmiapriyam/predator-prey/.venv/lib/python3.10/site-packages/ray/tune/trainable/trainable.py", line 342, in train
    raise skipped from exception_cause(skipped)
  File "/data/gpfs/projects/punim1355/dalmiapriyam/predator-prey/.venv/lib/python3.10/site-packages/ray/air/_internal/util.py", line 91, in run
    self._ret = self._target(*self._args, **self._kwargs)
  File "/data/gpfs/projects/punim1355/dalmiapriyam/predator-prey/.venv/lib/python3.10/site-packages/ray/tune/trainable/function_trainable.py", line 115, in <lambda>
    training_func=lambda: self._trainable_func(self.config),
  File "/data/gpfs/projects/punim1355/dalmiapriyam/predator-prey/.venv/lib/python3.10/site-packages/ray/tune/trainable/function_trainable.py", line 332, in _trainable_func
    output = fn()
  File "/data/gpfs/projects/punim1355/dalmiapriyam/predator-prey/./train.py", line 211, in train_algo
    wandb.init(
  File "/data/gpfs/projects/punim1355/dalmiapriyam/predator-prey/.venv/lib/python3.10/site-packages/wandb/sdk/wandb_init.py", line 1204, in init
    raise Error("An unexpected error occurred") from error_seen
wandb.errors.Error: An unexpected error occurred
2023-12-06 22:48:59,041	ERROR tune_controller.py:1383 -- Trial task failed for trial train_algo_64c6a_00001
Traceback (most recent call last):
  File "/data/gpfs/projects/punim1355/dalmiapriyam/predator-prey/.venv/lib/python3.10/site-packages/ray/air/execution/_internal/event_manager.py", line 110, in resolve_future
    result = ray.get(future)
  File "/data/gpfs/projects/punim1355/dalmiapriyam/predator-prey/.venv/lib/python3.10/site-packages/ray/_private/auto_init_hook.py", line 24, in auto_init_wrapper
    return fn(*args, **kwargs)
  File "/data/gpfs/projects/punim1355/dalmiapriyam/predator-prey/.venv/lib/python3.10/site-packages/ray/_private/client_mode_hook.py", line 103, in wrapper
    return func(*args, **kwargs)
  File "/data/gpfs/projects/punim1355/dalmiapriyam/predator-prey/.venv/lib/python3.10/site-packages/ray/_private/worker.py", line 2563, in get
    raise value.as_instanceof_cause()
ray.exceptions.RayTaskError(Error): [36mray::ImplicitFunc.train()[39m (pid=96887, ip=172.26.93.143, actor_id=16f1478c0f751a1e0b2b65ec01000000, repr=train_algo)
  File "/data/gpfs/projects/punim1355/dalmiapriyam/predator-prey/.venv/lib/python3.10/site-packages/wandb/sdk/wandb_init.py", line 189, in setup
    self._wl = wandb_setup.setup(settings=setup_settings)
  File "/data/gpfs/projects/punim1355/dalmiapriyam/predator-prey/.venv/lib/python3.10/site-packages/wandb/sdk/wandb_setup.py", line 327, in setup
    ret = _setup(settings=settings)
  File "/data/gpfs/projects/punim1355/dalmiapriyam/predator-prey/.venv/lib/python3.10/site-packages/wandb/sdk/wandb_setup.py", line 320, in _setup
    wl = _WandbSetup(settings=settings)
  File "/data/gpfs/projects/punim1355/dalmiapriyam/predator-prey/.venv/lib/python3.10/site-packages/wandb/sdk/wandb_setup.py", line 303, in __init__
    _WandbSetup._instance = _WandbSetup__WandbSetup(settings=settings, pid=pid)
  File "/data/gpfs/projects/punim1355/dalmiapriyam/predator-prey/.venv/lib/python3.10/site-packages/wandb/sdk/wandb_setup.py", line 114, in __init__
    self._setup()
  File "/data/gpfs/projects/punim1355/dalmiapriyam/predator-prey/.venv/lib/python3.10/site-packages/wandb/sdk/wandb_setup.py", line 250, in _setup
    self._setup_manager()
  File "/data/gpfs/projects/punim1355/dalmiapriyam/predator-prey/.venv/lib/python3.10/site-packages/wandb/sdk/wandb_setup.py", line 277, in _setup_manager
    self._manager = wandb_manager._Manager(settings=self._settings)
  File "/data/gpfs/projects/punim1355/dalmiapriyam/predator-prey/.venv/lib/python3.10/site-packages/wandb/sdk/wandb_manager.py", line 138, in __init__
    self._service.start()
  File "/data/gpfs/projects/punim1355/dalmiapriyam/predator-prey/.venv/lib/python3.10/site-packages/wandb/sdk/service/service.py", line 258, in start
    self._launch_server()
  File "/data/gpfs/projects/punim1355/dalmiapriyam/predator-prey/.venv/lib/python3.10/site-packages/wandb/sdk/service/service.py", line 164, in _launch_server
    with tempfile.TemporaryDirectory() as tmpdir:
  File "/apps/easybuild-2022/easybuild/software/Compiler/GCCcore/11.3.0/Python/3.10.4/lib/python3.10/tempfile.py", line 796, in __init__
    self.name = mkdtemp(suffix, prefix, dir)
  File "/apps/easybuild-2022/easybuild/software/Compiler/GCCcore/11.3.0/Python/3.10.4/lib/python3.10/tempfile.py", line 368, in mkdtemp
    _os.mkdir(file, 0o700)
FileNotFoundError: [Errno 2] No such file or directory: '/tmp/tmpgns7441s'

The above exception was the direct cause of the following exception:

[36mray::ImplicitFunc.train()[39m (pid=96887, ip=172.26.93.143, actor_id=16f1478c0f751a1e0b2b65ec01000000, repr=train_algo)
  File "/data/gpfs/projects/punim1355/dalmiapriyam/predator-prey/.venv/lib/python3.10/site-packages/ray/tune/trainable/trainable.py", line 342, in train
    raise skipped from exception_cause(skipped)
  File "/data/gpfs/projects/punim1355/dalmiapriyam/predator-prey/.venv/lib/python3.10/site-packages/ray/air/_internal/util.py", line 91, in run
    self._ret = self._target(*self._args, **self._kwargs)
  File "/data/gpfs/projects/punim1355/dalmiapriyam/predator-prey/.venv/lib/python3.10/site-packages/ray/tune/trainable/function_trainable.py", line 115, in <lambda>
    training_func=lambda: self._trainable_func(self.config),
  File "/data/gpfs/projects/punim1355/dalmiapriyam/predator-prey/.venv/lib/python3.10/site-packages/ray/tune/trainable/function_trainable.py", line 332, in _trainable_func
    output = fn()
  File "/data/gpfs/projects/punim1355/dalmiapriyam/predator-prey/./train.py", line 211, in train_algo
    wandb.init(
  File "/data/gpfs/projects/punim1355/dalmiapriyam/predator-prey/.venv/lib/python3.10/site-packages/wandb/sdk/wandb_init.py", line 1204, in init
    raise Error("An unexpected error occurred") from error_seen
wandb.errors.Error: An unexpected error occurred
2023-12-06 22:48:59,050	ERROR tune_controller.py:1383 -- Trial task failed for trial train_algo_64c6a_00000
Traceback (most recent call last):
  File "/data/gpfs/projects/punim1355/dalmiapriyam/predator-prey/.venv/lib/python3.10/site-packages/ray/air/execution/_internal/event_manager.py", line 110, in resolve_future
    result = ray.get(future)
  File "/data/gpfs/projects/punim1355/dalmiapriyam/predator-prey/.venv/lib/python3.10/site-packages/ray/_private/auto_init_hook.py", line 24, in auto_init_wrapper
    return fn(*args, **kwargs)
  File "/data/gpfs/projects/punim1355/dalmiapriyam/predator-prey/.venv/lib/python3.10/site-packages/ray/_private/client_mode_hook.py", line 103, in wrapper
    return func(*args, **kwargs)
  File "/data/gpfs/projects/punim1355/dalmiapriyam/predator-prey/.venv/lib/python3.10/site-packages/ray/_private/worker.py", line 2563, in get
    raise value.as_instanceof_cause()
ray.exceptions.RayTaskError(Error): [36mray::ImplicitFunc.train()[39m (pid=96886, ip=172.26.93.143, actor_id=14bb2ab8a05acebb9a869ef601000000, repr=train_algo)
  File "/data/gpfs/projects/punim1355/dalmiapriyam/predator-prey/.venv/lib/python3.10/site-packages/wandb/sdk/wandb_init.py", line 189, in setup
    self._wl = wandb_setup.setup(settings=setup_settings)
  File "/data/gpfs/projects/punim1355/dalmiapriyam/predator-prey/.venv/lib/python3.10/site-packages/wandb/sdk/wandb_setup.py", line 327, in setup
    ret = _setup(settings=settings)
  File "/data/gpfs/projects/punim1355/dalmiapriyam/predator-prey/.venv/lib/python3.10/site-packages/wandb/sdk/wandb_setup.py", line 320, in _setup
    wl = _WandbSetup(settings=settings)
  File "/data/gpfs/projects/punim1355/dalmiapriyam/predator-prey/.venv/lib/python3.10/site-packages/wandb/sdk/wandb_setup.py", line 303, in __init__
    _WandbSetup._instance = _WandbSetup__WandbSetup(settings=settings, pid=pid)
  File "/data/gpfs/projects/punim1355/dalmiapriyam/predator-prey/.venv/lib/python3.10/site-packages/wandb/sdk/wandb_setup.py", line 114, in __init__
    self._setup()
  File "/data/gpfs/projects/punim1355/dalmiapriyam/predator-prey/.venv/lib/python3.10/site-packages/wandb/sdk/wandb_setup.py", line 250, in _setup
    self._setup_manager()
  File "/data/gpfs/projects/punim1355/dalmiapriyam/predator-prey/.venv/lib/python3.10/site-packages/wandb/sdk/wandb_setup.py", line 277, in _setup_manager
    self._manager = wandb_manager._Manager(settings=self._settings)
  File "/data/gpfs/projects/punim1355/dalmiapriyam/predator-prey/.venv/lib/python3.10/site-packages/wandb/sdk/wandb_manager.py", line 138, in __init__
    self._service.start()
  File "/data/gpfs/projects/punim1355/dalmiapriyam/predator-prey/.venv/lib/python3.10/site-packages/wandb/sdk/service/service.py", line 258, in start
    self._launch_server()
  File "/data/gpfs/projects/punim1355/dalmiapriyam/predator-prey/.venv/lib/python3.10/site-packages/wandb/sdk/service/service.py", line 164, in _launch_server
    with tempfile.TemporaryDirectory() as tmpdir:
  File "/apps/easybuild-2022/easybuild/software/Compiler/GCCcore/11.3.0/Python/3.10.4/lib/python3.10/tempfile.py", line 796, in __init__
    self.name = mkdtemp(suffix, prefix, dir)
  File "/apps/easybuild-2022/easybuild/software/Compiler/GCCcore/11.3.0/Python/3.10.4/lib/python3.10/tempfile.py", line 368, in mkdtemp
    _os.mkdir(file, 0o700)
FileNotFoundError: [Errno 2] No such file or directory: '/tmp/tmpf4w2j8kw'

The above exception was the direct cause of the following exception:

[36mray::ImplicitFunc.train()[39m (pid=96886, ip=172.26.93.143, actor_id=14bb2ab8a05acebb9a869ef601000000, repr=train_algo)
  File "/data/gpfs/projects/punim1355/dalmiapriyam/predator-prey/.venv/lib/python3.10/site-packages/ray/tune/trainable/trainable.py", line 342, in train
    raise skipped from exception_cause(skipped)
  File "/data/gpfs/projects/punim1355/dalmiapriyam/predator-prey/.venv/lib/python3.10/site-packages/ray/air/_internal/util.py", line 91, in run
    self._ret = self._target(*self._args, **self._kwargs)
  File "/data/gpfs/projects/punim1355/dalmiapriyam/predator-prey/.venv/lib/python3.10/site-packages/ray/tune/trainable/function_trainable.py", line 115, in <lambda>
    training_func=lambda: self._trainable_func(self.config),
  File "/data/gpfs/projects/punim1355/dalmiapriyam/predator-prey/.venv/lib/python3.10/site-packages/ray/tune/trainable/function_trainable.py", line 332, in _trainable_func
    output = fn()
  File "/data/gpfs/projects/punim1355/dalmiapriyam/predator-prey/./train.py", line 211, in train_algo
    wandb.init(
  File "/data/gpfs/projects/punim1355/dalmiapriyam/predator-prey/.venv/lib/python3.10/site-packages/wandb/sdk/wandb_init.py", line 1204, in init
    raise Error("An unexpected error occurred") from error_seen
wandb.errors.Error: An unexpected error occurred
2023-12-06 22:48:59,059	ERROR tune_controller.py:1383 -- Trial task failed for trial train_algo_64c6a_00021
Traceback (most recent call last):
  File "/data/gpfs/projects/punim1355/dalmiapriyam/predator-prey/.venv/lib/python3.10/site-packages/ray/air/execution/_internal/event_manager.py", line 110, in resolve_future
    result = ray.get(future)
  File "/data/gpfs/projects/punim1355/dalmiapriyam/predator-prey/.venv/lib/python3.10/site-packages/ray/_private/auto_init_hook.py", line 24, in auto_init_wrapper
    return fn(*args, **kwargs)
  File "/data/gpfs/projects/punim1355/dalmiapriyam/predator-prey/.venv/lib/python3.10/site-packages/ray/_private/client_mode_hook.py", line 103, in wrapper
    return func(*args, **kwargs)
  File "/data/gpfs/projects/punim1355/dalmiapriyam/predator-prey/.venv/lib/python3.10/site-packages/ray/_private/worker.py", line 2563, in get
    raise value.as_instanceof_cause()
ray.exceptions.RayTaskError(Error): [36mray::ImplicitFunc.train()[39m (pid=96907, ip=172.26.93.143, actor_id=e5b9d94875b2efea293987ef01000000, repr=train_algo)
  File "/data/gpfs/projects/punim1355/dalmiapriyam/predator-prey/.venv/lib/python3.10/site-packages/wandb/sdk/wandb_init.py", line 189, in setup
    self._wl = wandb_setup.setup(settings=setup_settings)
  File "/data/gpfs/projects/punim1355/dalmiapriyam/predator-prey/.venv/lib/python3.10/site-packages/wandb/sdk/wandb_setup.py", line 327, in setup
    ret = _setup(settings=settings)
  File "/data/gpfs/projects/punim1355/dalmiapriyam/predator-prey/.venv/lib/python3.10/site-packages/wandb/sdk/wandb_setup.py", line 320, in _setup
    wl = _WandbSetup(settings=settings)
  File "/data/gpfs/projects/punim1355/dalmiapriyam/predator-prey/.venv/lib/python3.10/site-packages/wandb/sdk/wandb_setup.py", line 303, in __init__
    _WandbSetup._instance = _WandbSetup__WandbSetup(settings=settings, pid=pid)
  File "/data/gpfs/projects/punim1355/dalmiapriyam/predator-prey/.venv/lib/python3.10/site-packages/wandb/sdk/wandb_setup.py", line 114, in __init__
    self._setup()
  File "/data/gpfs/projects/punim1355/dalmiapriyam/predator-prey/.venv/lib/python3.10/site-packages/wandb/sdk/wandb_setup.py", line 250, in _setup
    self._setup_manager()
  File "/data/gpfs/projects/punim1355/dalmiapriyam/predator-prey/.venv/lib/python3.10/site-packages/wandb/sdk/wandb_setup.py", line 277, in _setup_manager
    self._manager = wandb_manager._Manager(settings=self._settings)
  File "/data/gpfs/projects/punim1355/dalmiapriyam/predator-prey/.venv/lib/python3.10/site-packages/wandb/sdk/wandb_manager.py", line 138, in __init__
    self._service.start()
  File "/data/gpfs/projects/punim1355/dalmiapriyam/predator-prey/.venv/lib/python3.10/site-packages/wandb/sdk/service/service.py", line 258, in start
    self._launch_server()
  File "/data/gpfs/projects/punim1355/dalmiapriyam/predator-prey/.venv/lib/python3.10/site-packages/wandb/sdk/service/service.py", line 164, in _launch_server
    with tempfile.TemporaryDirectory() as tmpdir:
  File "/apps/easybuild-2022/easybuild/software/Compiler/GCCcore/11.3.0/Python/3.10.4/lib/python3.10/tempfile.py", line 796, in __init__
    self.name = mkdtemp(suffix, prefix, dir)
  File "/apps/easybuild-2022/easybuild/software/Compiler/GCCcore/11.3.0/Python/3.10.4/lib/python3.10/tempfile.py", line 368, in mkdtemp
    _os.mkdir(file, 0o700)
FileNotFoundError: [Errno 2] No such file or directory: '/tmp/tmpr1izcdtw'

The above exception was the direct cause of the following exception:

[36mray::ImplicitFunc.train()[39m (pid=96907, ip=172.26.93.143, actor_id=e5b9d94875b2efea293987ef01000000, repr=train_algo)
  File "/data/gpfs/projects/punim1355/dalmiapriyam/predator-prey/.venv/lib/python3.10/site-packages/ray/tune/trainable/trainable.py", line 342, in train
    raise skipped from exception_cause(skipped)
  File "/data/gpfs/projects/punim1355/dalmiapriyam/predator-prey/.venv/lib/python3.10/site-packages/ray/air/_internal/util.py", line 91, in run
    self._ret = self._target(*self._args, **self._kwargs)
  File "/data/gpfs/projects/punim1355/dalmiapriyam/predator-prey/.venv/lib/python3.10/site-packages/ray/tune/trainable/function_trainable.py", line 115, in <lambda>
    training_func=lambda: self._trainable_func(self.config),
  File "/data/gpfs/projects/punim1355/dalmiapriyam/predator-prey/.venv/lib/python3.10/site-packages/ray/tune/trainable/function_trainable.py", line 332, in _trainable_func
    output = fn()
  File "/data/gpfs/projects/punim1355/dalmiapriyam/predator-prey/./train.py", line 211, in train_algo
    wandb.init(
  File "/data/gpfs/projects/punim1355/dalmiapriyam/predator-prey/.venv/lib/python3.10/site-packages/wandb/sdk/wandb_init.py", line 1204, in init
    raise Error("An unexpected error occurred") from error_seen
wandb.errors.Error: An unexpected error occurred
2023-12-06 22:48:59,069	ERROR tune_controller.py:1383 -- Trial task failed for trial train_algo_64c6a_00023
Traceback (most recent call last):
  File "/data/gpfs/projects/punim1355/dalmiapriyam/predator-prey/.venv/lib/python3.10/site-packages/ray/air/execution/_internal/event_manager.py", line 110, in resolve_future
    result = ray.get(future)
  File "/data/gpfs/projects/punim1355/dalmiapriyam/predator-prey/.venv/lib/python3.10/site-packages/ray/_private/auto_init_hook.py", line 24, in auto_init_wrapper
    return fn(*args, **kwargs)
  File "/data/gpfs/projects/punim1355/dalmiapriyam/predator-prey/.venv/lib/python3.10/site-packages/ray/_private/client_mode_hook.py", line 103, in wrapper
    return func(*args, **kwargs)
  File "/data/gpfs/projects/punim1355/dalmiapriyam/predator-prey/.venv/lib/python3.10/site-packages/ray/_private/worker.py", line 2563, in get
    raise value.as_instanceof_cause()
ray.exceptions.RayTaskError(Error): [36mray::ImplicitFunc.train()[39m (pid=96909, ip=172.26.93.143, actor_id=8e1b3930e1f10940a60366ec01000000, repr=train_algo)
  File "/data/gpfs/projects/punim1355/dalmiapriyam/predator-prey/.venv/lib/python3.10/site-packages/wandb/sdk/wandb_init.py", line 189, in setup
    self._wl = wandb_setup.setup(settings=setup_settings)
  File "/data/gpfs/projects/punim1355/dalmiapriyam/predator-prey/.venv/lib/python3.10/site-packages/wandb/sdk/wandb_setup.py", line 327, in setup
    ret = _setup(settings=settings)
  File "/data/gpfs/projects/punim1355/dalmiapriyam/predator-prey/.venv/lib/python3.10/site-packages/wandb/sdk/wandb_setup.py", line 320, in _setup
    wl = _WandbSetup(settings=settings)
  File "/data/gpfs/projects/punim1355/dalmiapriyam/predator-prey/.venv/lib/python3.10/site-packages/wandb/sdk/wandb_setup.py", line 303, in __init__
    _WandbSetup._instance = _WandbSetup__WandbSetup(settings=settings, pid=pid)
  File "/data/gpfs/projects/punim1355/dalmiapriyam/predator-prey/.venv/lib/python3.10/site-packages/wandb/sdk/wandb_setup.py", line 114, in __init__
    self._setup()
  File "/data/gpfs/projects/punim1355/dalmiapriyam/predator-prey/.venv/lib/python3.10/site-packages/wandb/sdk/wandb_setup.py", line 250, in _setup
    self._setup_manager()
  File "/data/gpfs/projects/punim1355/dalmiapriyam/predator-prey/.venv/lib/python3.10/site-packages/wandb/sdk/wandb_setup.py", line 277, in _setup_manager
    self._manager = wandb_manager._Manager(settings=self._settings)
  File "/data/gpfs/projects/punim1355/dalmiapriyam/predator-prey/.venv/lib/python3.10/site-packages/wandb/sdk/wandb_manager.py", line 138, in __init__
    self._service.start()
  File "/data/gpfs/projects/punim1355/dalmiapriyam/predator-prey/.venv/lib/python3.10/site-packages/wandb/sdk/service/service.py", line 258, in start
    self._launch_server()
  File "/data/gpfs/projects/punim1355/dalmiapriyam/predator-prey/.venv/lib/python3.10/site-packages/wandb/sdk/service/service.py", line 164, in _launch_server
    with tempfile.TemporaryDirectory() as tmpdir:
  File "/apps/easybuild-2022/easybuild/software/Compiler/GCCcore/11.3.0/Python/3.10.4/lib/python3.10/tempfile.py", line 796, in __init__
    self.name = mkdtemp(suffix, prefix, dir)
  File "/apps/easybuild-2022/easybuild/software/Compiler/GCCcore/11.3.0/Python/3.10.4/lib/python3.10/tempfile.py", line 368, in mkdtemp
    _os.mkdir(file, 0o700)
FileNotFoundError: [Errno 2] No such file or directory: '/tmp/tmp9t_hu0e8'

The above exception was the direct cause of the following exception:

[36mray::ImplicitFunc.train()[39m (pid=96909, ip=172.26.93.143, actor_id=8e1b3930e1f10940a60366ec01000000, repr=train_algo)
  File "/data/gpfs/projects/punim1355/dalmiapriyam/predator-prey/.venv/lib/python3.10/site-packages/ray/tune/trainable/trainable.py", line 342, in train
    raise skipped from exception_cause(skipped)
  File "/data/gpfs/projects/punim1355/dalmiapriyam/predator-prey/.venv/lib/python3.10/site-packages/ray/air/_internal/util.py", line 91, in run
    self._ret = self._target(*self._args, **self._kwargs)
  File "/data/gpfs/projects/punim1355/dalmiapriyam/predator-prey/.venv/lib/python3.10/site-packages/ray/tune/trainable/function_trainable.py", line 115, in <lambda>
    training_func=lambda: self._trainable_func(self.config),
  File "/data/gpfs/projects/punim1355/dalmiapriyam/predator-prey/.venv/lib/python3.10/site-packages/ray/tune/trainable/function_trainable.py", line 332, in _trainable_func
    output = fn()
  File "/data/gpfs/projects/punim1355/dalmiapriyam/predator-prey/./train.py", line 211, in train_algo
    wandb.init(
  File "/data/gpfs/projects/punim1355/dalmiapriyam/predator-prey/.venv/lib/python3.10/site-packages/wandb/sdk/wandb_init.py", line 1204, in init
    raise Error("An unexpected error occurred") from error_seen
wandb.errors.Error: An unexpected error occurred
2023-12-06 22:48:59,077	ERROR tune_controller.py:1383 -- Trial task failed for trial train_algo_64c6a_00005
Traceback (most recent call last):
  File "/data/gpfs/projects/punim1355/dalmiapriyam/predator-prey/.venv/lib/python3.10/site-packages/ray/air/execution/_internal/event_manager.py", line 110, in resolve_future
    result = ray.get(future)
  File "/data/gpfs/projects/punim1355/dalmiapriyam/predator-prey/.venv/lib/python3.10/site-packages/ray/_private/auto_init_hook.py", line 24, in auto_init_wrapper
    return fn(*args, **kwargs)
  File "/data/gpfs/projects/punim1355/dalmiapriyam/predator-prey/.venv/lib/python3.10/site-packages/ray/_private/client_mode_hook.py", line 103, in wrapper
    return func(*args, **kwargs)
  File "/data/gpfs/projects/punim1355/dalmiapriyam/predator-prey/.venv/lib/python3.10/site-packages/ray/_private/worker.py", line 2563, in get
    raise value.as_instanceof_cause()
ray.exceptions.RayTaskError(Error): [36mray::ImplicitFunc.train()[39m (pid=96893, ip=172.26.93.143, actor_id=f6a9d63e03d8870b5d70732901000000, repr=train_algo)
  File "/data/gpfs/projects/punim1355/dalmiapriyam/predator-prey/.venv/lib/python3.10/site-packages/wandb/sdk/wandb_init.py", line 189, in setup
    self._wl = wandb_setup.setup(settings=setup_settings)
  File "/data/gpfs/projects/punim1355/dalmiapriyam/predator-prey/.venv/lib/python3.10/site-packages/wandb/sdk/wandb_setup.py", line 327, in setup
    ret = _setup(settings=settings)
  File "/data/gpfs/projects/punim1355/dalmiapriyam/predator-prey/.venv/lib/python3.10/site-packages/wandb/sdk/wandb_setup.py", line 320, in _setup
    wl = _WandbSetup(settings=settings)
  File "/data/gpfs/projects/punim1355/dalmiapriyam/predator-prey/.venv/lib/python3.10/site-packages/wandb/sdk/wandb_setup.py", line 303, in __init__
    _WandbSetup._instance = _WandbSetup__WandbSetup(settings=settings, pid=pid)
  File "/data/gpfs/projects/punim1355/dalmiapriyam/predator-prey/.venv/lib/python3.10/site-packages/wandb/sdk/wandb_setup.py", line 114, in __init__
    self._setup()
  File "/data/gpfs/projects/punim1355/dalmiapriyam/predator-prey/.venv/lib/python3.10/site-packages/wandb/sdk/wandb_setup.py", line 250, in _setup
    self._setup_manager()
  File "/data/gpfs/projects/punim1355/dalmiapriyam/predator-prey/.venv/lib/python3.10/site-packages/wandb/sdk/wandb_setup.py", line 277, in _setup_manager
    self._manager = wandb_manager._Manager(settings=self._settings)
  File "/data/gpfs/projects/punim1355/dalmiapriyam/predator-prey/.venv/lib/python3.10/site-packages/wandb/sdk/wandb_manager.py", line 138, in __init__
    self._service.start()
  File "/data/gpfs/projects/punim1355/dalmiapriyam/predator-prey/.venv/lib/python3.10/site-packages/wandb/sdk/service/service.py", line 258, in start
    self._launch_server()
  File "/data/gpfs/projects/punim1355/dalmiapriyam/predator-prey/.venv/lib/python3.10/site-packages/wandb/sdk/service/service.py", line 164, in _launch_server
    with tempfile.TemporaryDirectory() as tmpdir:
  File "/apps/easybuild-2022/easybuild/software/Compiler/GCCcore/11.3.0/Python/3.10.4/lib/python3.10/tempfile.py", line 796, in __init__
    self.name = mkdtemp(suffix, prefix, dir)
  File "/apps/easybuild-2022/easybuild/software/Compiler/GCCcore/11.3.0/Python/3.10.4/lib/python3.10/tempfile.py", line 368, in mkdtemp
    _os.mkdir(file, 0o700)
FileNotFoundError: [Errno 2] No such file or directory: '/tmp/tmpyjxkd4xx'

The above exception was the direct cause of the following exception:

[36mray::ImplicitFunc.train()[39m (pid=96893, ip=172.26.93.143, actor_id=f6a9d63e03d8870b5d70732901000000, repr=train_algo)
  File "/data/gpfs/projects/punim1355/dalmiapriyam/predator-prey/.venv/lib/python3.10/site-packages/ray/tune/trainable/trainable.py", line 342, in train
    raise skipped from exception_cause(skipped)
  File "/data/gpfs/projects/punim1355/dalmiapriyam/predator-prey/.venv/lib/python3.10/site-packages/ray/air/_internal/util.py", line 91, in run
    self._ret = self._target(*self._args, **self._kwargs)
  File "/data/gpfs/projects/punim1355/dalmiapriyam/predator-prey/.venv/lib/python3.10/site-packages/ray/tune/trainable/function_trainable.py", line 115, in <lambda>
    training_func=lambda: self._trainable_func(self.config),
  File "/data/gpfs/projects/punim1355/dalmiapriyam/predator-prey/.venv/lib/python3.10/site-packages/ray/tune/trainable/function_trainable.py", line 332, in _trainable_func
    output = fn()
  File "/data/gpfs/projects/punim1355/dalmiapriyam/predator-prey/./train.py", line 211, in train_algo
    wandb.init(
  File "/data/gpfs/projects/punim1355/dalmiapriyam/predator-prey/.venv/lib/python3.10/site-packages/wandb/sdk/wandb_init.py", line 1204, in init
    raise Error("An unexpected error occurred") from error_seen
wandb.errors.Error: An unexpected error occurred
2023-12-06 22:48:59,088	ERROR tune_controller.py:1383 -- Trial task failed for trial train_algo_64c6a_00002
Traceback (most recent call last):
  File "/data/gpfs/projects/punim1355/dalmiapriyam/predator-prey/.venv/lib/python3.10/site-packages/ray/air/execution/_internal/event_manager.py", line 110, in resolve_future
    result = ray.get(future)
  File "/data/gpfs/projects/punim1355/dalmiapriyam/predator-prey/.venv/lib/python3.10/site-packages/ray/_private/auto_init_hook.py", line 24, in auto_init_wrapper
    return fn(*args, **kwargs)
  File "/data/gpfs/projects/punim1355/dalmiapriyam/predator-prey/.venv/lib/python3.10/site-packages/ray/_private/client_mode_hook.py", line 103, in wrapper
    return func(*args, **kwargs)
  File "/data/gpfs/projects/punim1355/dalmiapriyam/predator-prey/.venv/lib/python3.10/site-packages/ray/_private/worker.py", line 2563, in get
    raise value.as_instanceof_cause()
ray.exceptions.RayTaskError(Error): [36mray::ImplicitFunc.train()[39m (pid=96888, ip=172.26.93.143, actor_id=966c091af61be344e5300b0a01000000, repr=train_algo)
  File "/data/gpfs/projects/punim1355/dalmiapriyam/predator-prey/.venv/lib/python3.10/site-packages/wandb/sdk/wandb_init.py", line 189, in setup
    self._wl = wandb_setup.setup(settings=setup_settings)
  File "/data/gpfs/projects/punim1355/dalmiapriyam/predator-prey/.venv/lib/python3.10/site-packages/wandb/sdk/wandb_setup.py", line 327, in setup
    ret = _setup(settings=settings)
  File "/data/gpfs/projects/punim1355/dalmiapriyam/predator-prey/.venv/lib/python3.10/site-packages/wandb/sdk/wandb_setup.py", line 320, in _setup
    wl = _WandbSetup(settings=settings)
  File "/data/gpfs/projects/punim1355/dalmiapriyam/predator-prey/.venv/lib/python3.10/site-packages/wandb/sdk/wandb_setup.py", line 303, in __init__
    _WandbSetup._instance = _WandbSetup__WandbSetup(settings=settings, pid=pid)
  File "/data/gpfs/projects/punim1355/dalmiapriyam/predator-prey/.venv/lib/python3.10/site-packages/wandb/sdk/wandb_setup.py", line 114, in __init__
    self._setup()
  File "/data/gpfs/projects/punim1355/dalmiapriyam/predator-prey/.venv/lib/python3.10/site-packages/wandb/sdk/wandb_setup.py", line 250, in _setup
    self._setup_manager()
  File "/data/gpfs/projects/punim1355/dalmiapriyam/predator-prey/.venv/lib/python3.10/site-packages/wandb/sdk/wandb_setup.py", line 277, in _setup_manager
    self._manager = wandb_manager._Manager(settings=self._settings)
  File "/data/gpfs/projects/punim1355/dalmiapriyam/predator-prey/.venv/lib/python3.10/site-packages/wandb/sdk/wandb_manager.py", line 138, in __init__
    self._service.start()
  File "/data/gpfs/projects/punim1355/dalmiapriyam/predator-prey/.venv/lib/python3.10/site-packages/wandb/sdk/service/service.py", line 258, in start
    self._launch_server()
  File "/data/gpfs/projects/punim1355/dalmiapriyam/predator-prey/.venv/lib/python3.10/site-packages/wandb/sdk/service/service.py", line 164, in _launch_server
    with tempfile.TemporaryDirectory() as tmpdir:
  File "/apps/easybuild-2022/easybuild/software/Compiler/GCCcore/11.3.0/Python/3.10.4/lib/python3.10/tempfile.py", line 796, in __init__
    self.name = mkdtemp(suffix, prefix, dir)
  File "/apps/easybuild-2022/easybuild/software/Compiler/GCCcore/11.3.0/Python/3.10.4/lib/python3.10/tempfile.py", line 368, in mkdtemp
    _os.mkdir(file, 0o700)
FileNotFoundError: [Errno 2] No such file or directory: '/tmp/tmp__bddiyz'

The above exception was the direct cause of the following exception:

[36mray::ImplicitFunc.train()[39m (pid=96888, ip=172.26.93.143, actor_id=966c091af61be344e5300b0a01000000, repr=train_algo)
  File "/data/gpfs/projects/punim1355/dalmiapriyam/predator-prey/.venv/lib/python3.10/site-packages/ray/tune/trainable/trainable.py", line 342, in train
    raise skipped from exception_cause(skipped)
  File "/data/gpfs/projects/punim1355/dalmiapriyam/predator-prey/.venv/lib/python3.10/site-packages/ray/air/_internal/util.py", line 91, in run
    self._ret = self._target(*self._args, **self._kwargs)
  File "/data/gpfs/projects/punim1355/dalmiapriyam/predator-prey/.venv/lib/python3.10/site-packages/ray/tune/trainable/function_trainable.py", line 115, in <lambda>
    training_func=lambda: self._trainable_func(self.config),
  File "/data/gpfs/projects/punim1355/dalmiapriyam/predator-prey/.venv/lib/python3.10/site-packages/ray/tune/trainable/function_trainable.py", line 332, in _trainable_func
    output = fn()
  File "/data/gpfs/projects/punim1355/dalmiapriyam/predator-prey/./train.py", line 211, in train_algo
    wandb.init(
  File "/data/gpfs/projects/punim1355/dalmiapriyam/predator-prey/.venv/lib/python3.10/site-packages/wandb/sdk/wandb_init.py", line 1204, in init
    raise Error("An unexpected error occurred") from error_seen
wandb.errors.Error: An unexpected error occurred
2023-12-06 22:48:59,097	ERROR tune_controller.py:1383 -- Trial task failed for trial train_algo_64c6a_00009
Traceback (most recent call last):
  File "/data/gpfs/projects/punim1355/dalmiapriyam/predator-prey/.venv/lib/python3.10/site-packages/ray/air/execution/_internal/event_manager.py", line 110, in resolve_future
    result = ray.get(future)
  File "/data/gpfs/projects/punim1355/dalmiapriyam/predator-prey/.venv/lib/python3.10/site-packages/ray/_private/auto_init_hook.py", line 24, in auto_init_wrapper
    return fn(*args, **kwargs)
  File "/data/gpfs/projects/punim1355/dalmiapriyam/predator-prey/.venv/lib/python3.10/site-packages/ray/_private/client_mode_hook.py", line 103, in wrapper
    return func(*args, **kwargs)
  File "/data/gpfs/projects/punim1355/dalmiapriyam/predator-prey/.venv/lib/python3.10/site-packages/ray/_private/worker.py", line 2563, in get
    raise value.as_instanceof_cause()
ray.exceptions.RayTaskError(Error): [36mray::ImplicitFunc.train()[39m (pid=96895, ip=172.26.93.143, actor_id=3e69e434e2c130989f4ad0f401000000, repr=train_algo)
  File "/data/gpfs/projects/punim1355/dalmiapriyam/predator-prey/.venv/lib/python3.10/site-packages/wandb/sdk/wandb_init.py", line 189, in setup
    self._wl = wandb_setup.setup(settings=setup_settings)
  File "/data/gpfs/projects/punim1355/dalmiapriyam/predator-prey/.venv/lib/python3.10/site-packages/wandb/sdk/wandb_setup.py", line 327, in setup
    ret = _setup(settings=settings)
  File "/data/gpfs/projects/punim1355/dalmiapriyam/predator-prey/.venv/lib/python3.10/site-packages/wandb/sdk/wandb_setup.py", line 320, in _setup
    wl = _WandbSetup(settings=settings)
  File "/data/gpfs/projects/punim1355/dalmiapriyam/predator-prey/.venv/lib/python3.10/site-packages/wandb/sdk/wandb_setup.py", line 303, in __init__
    _WandbSetup._instance = _WandbSetup__WandbSetup(settings=settings, pid=pid)
  File "/data/gpfs/projects/punim1355/dalmiapriyam/predator-prey/.venv/lib/python3.10/site-packages/wandb/sdk/wandb_setup.py", line 114, in __init__
    self._setup()
  File "/data/gpfs/projects/punim1355/dalmiapriyam/predator-prey/.venv/lib/python3.10/site-packages/wandb/sdk/wandb_setup.py", line 250, in _setup
    self._setup_manager()
  File "/data/gpfs/projects/punim1355/dalmiapriyam/predator-prey/.venv/lib/python3.10/site-packages/wandb/sdk/wandb_setup.py", line 277, in _setup_manager
    self._manager = wandb_manager._Manager(settings=self._settings)
  File "/data/gpfs/projects/punim1355/dalmiapriyam/predator-prey/.venv/lib/python3.10/site-packages/wandb/sdk/wandb_manager.py", line 138, in __init__
    self._service.start()
  File "/data/gpfs/projects/punim1355/dalmiapriyam/predator-prey/.venv/lib/python3.10/site-packages/wandb/sdk/service/service.py", line 258, in start
    self._launch_server()
  File "/data/gpfs/projects/punim1355/dalmiapriyam/predator-prey/.venv/lib/python3.10/site-packages/wandb/sdk/service/service.py", line 164, in _launch_server
    with tempfile.TemporaryDirectory() as tmpdir:
  File "/apps/easybuild-2022/easybuild/software/Compiler/GCCcore/11.3.0/Python/3.10.4/lib/python3.10/tempfile.py", line 796, in __init__
    self.name = mkdtemp(suffix, prefix, dir)
  File "/apps/easybuild-2022/easybuild/software/Compiler/GCCcore/11.3.0/Python/3.10.4/lib/python3.10/tempfile.py", line 368, in mkdtemp
    _os.mkdir(file, 0o700)
FileNotFoundError: [Errno 2] No such file or directory: '/tmp/tmpgjmt_1fa'

The above exception was the direct cause of the following exception:

[36mray::ImplicitFunc.train()[39m (pid=96895, ip=172.26.93.143, actor_id=3e69e434e2c130989f4ad0f401000000, repr=train_algo)
  File "/data/gpfs/projects/punim1355/dalmiapriyam/predator-prey/.venv/lib/python3.10/site-packages/ray/tune/trainable/trainable.py", line 342, in train
    raise skipped from exception_cause(skipped)
  File "/data/gpfs/projects/punim1355/dalmiapriyam/predator-prey/.venv/lib/python3.10/site-packages/ray/air/_internal/util.py", line 91, in run
    self._ret = self._target(*self._args, **self._kwargs)
  File "/data/gpfs/projects/punim1355/dalmiapriyam/predator-prey/.venv/lib/python3.10/site-packages/ray/tune/trainable/function_trainable.py", line 115, in <lambda>
    training_func=lambda: self._trainable_func(self.config),
  File "/data/gpfs/projects/punim1355/dalmiapriyam/predator-prey/.venv/lib/python3.10/site-packages/ray/tune/trainable/function_trainable.py", line 332, in _trainable_func
    output = fn()
  File "/data/gpfs/projects/punim1355/dalmiapriyam/predator-prey/./train.py", line 211, in train_algo
    wandb.init(
  File "/data/gpfs/projects/punim1355/dalmiapriyam/predator-prey/.venv/lib/python3.10/site-packages/wandb/sdk/wandb_init.py", line 1204, in init
    raise Error("An unexpected error occurred") from error_seen
wandb.errors.Error: An unexpected error occurred
2023-12-06 22:48:59,107	ERROR tune_controller.py:1383 -- Trial task failed for trial train_algo_64c6a_00016
Traceback (most recent call last):
  File "/data/gpfs/projects/punim1355/dalmiapriyam/predator-prey/.venv/lib/python3.10/site-packages/ray/air/execution/_internal/event_manager.py", line 110, in resolve_future
    result = ray.get(future)
  File "/data/gpfs/projects/punim1355/dalmiapriyam/predator-prey/.venv/lib/python3.10/site-packages/ray/_private/auto_init_hook.py", line 24, in auto_init_wrapper
    return fn(*args, **kwargs)
  File "/data/gpfs/projects/punim1355/dalmiapriyam/predator-prey/.venv/lib/python3.10/site-packages/ray/_private/client_mode_hook.py", line 103, in wrapper
    return func(*args, **kwargs)
  File "/data/gpfs/projects/punim1355/dalmiapriyam/predator-prey/.venv/lib/python3.10/site-packages/ray/_private/worker.py", line 2563, in get
    raise value.as_instanceof_cause()
ray.exceptions.RayTaskError(Error): [36mray::ImplicitFunc.train()[39m (pid=96902, ip=172.26.93.143, actor_id=175b8c2e085999a9c9c87c2a01000000, repr=train_algo)
  File "/data/gpfs/projects/punim1355/dalmiapriyam/predator-prey/.venv/lib/python3.10/site-packages/wandb/sdk/wandb_init.py", line 189, in setup
    self._wl = wandb_setup.setup(settings=setup_settings)
  File "/data/gpfs/projects/punim1355/dalmiapriyam/predator-prey/.venv/lib/python3.10/site-packages/wandb/sdk/wandb_setup.py", line 327, in setup
    ret = _setup(settings=settings)
  File "/data/gpfs/projects/punim1355/dalmiapriyam/predator-prey/.venv/lib/python3.10/site-packages/wandb/sdk/wandb_setup.py", line 320, in _setup
    wl = _WandbSetup(settings=settings)
  File "/data/gpfs/projects/punim1355/dalmiapriyam/predator-prey/.venv/lib/python3.10/site-packages/wandb/sdk/wandb_setup.py", line 303, in __init__
    _WandbSetup._instance = _WandbSetup__WandbSetup(settings=settings, pid=pid)
  File "/data/gpfs/projects/punim1355/dalmiapriyam/predator-prey/.venv/lib/python3.10/site-packages/wandb/sdk/wandb_setup.py", line 114, in __init__
    self._setup()
  File "/data/gpfs/projects/punim1355/dalmiapriyam/predator-prey/.venv/lib/python3.10/site-packages/wandb/sdk/wandb_setup.py", line 250, in _setup
    self._setup_manager()
  File "/data/gpfs/projects/punim1355/dalmiapriyam/predator-prey/.venv/lib/python3.10/site-packages/wandb/sdk/wandb_setup.py", line 277, in _setup_manager
    self._manager = wandb_manager._Manager(settings=self._settings)
  File "/data/gpfs/projects/punim1355/dalmiapriyam/predator-prey/.venv/lib/python3.10/site-packages/wandb/sdk/wandb_manager.py", line 138, in __init__
    self._service.start()
  File "/data/gpfs/projects/punim1355/dalmiapriyam/predator-prey/.venv/lib/python3.10/site-packages/wandb/sdk/service/service.py", line 258, in start
    self._launch_server()
  File "/data/gpfs/projects/punim1355/dalmiapriyam/predator-prey/.venv/lib/python3.10/site-packages/wandb/sdk/service/service.py", line 164, in _launch_server
    with tempfile.TemporaryDirectory() as tmpdir:
  File "/apps/easybuild-2022/easybuild/software/Compiler/GCCcore/11.3.0/Python/3.10.4/lib/python3.10/tempfile.py", line 796, in __init__
    self.name = mkdtemp(suffix, prefix, dir)
  File "/apps/easybuild-2022/easybuild/software/Compiler/GCCcore/11.3.0/Python/3.10.4/lib/python3.10/tempfile.py", line 368, in mkdtemp
    _os.mkdir(file, 0o700)
FileNotFoundError: [Errno 2] No such file or directory: '/tmp/tmpnclsfktb'

The above exception was the direct cause of the following exception:

[36mray::ImplicitFunc.train()[39m (pid=96902, ip=172.26.93.143, actor_id=175b8c2e085999a9c9c87c2a01000000, repr=train_algo)
  File "/data/gpfs/projects/punim1355/dalmiapriyam/predator-prey/.venv/lib/python3.10/site-packages/ray/tune/trainable/trainable.py", line 342, in train
    raise skipped from exception_cause(skipped)
  File "/data/gpfs/projects/punim1355/dalmiapriyam/predator-prey/.venv/lib/python3.10/site-packages/ray/air/_internal/util.py", line 91, in run
    self._ret = self._target(*self._args, **self._kwargs)
  File "/data/gpfs/projects/punim1355/dalmiapriyam/predator-prey/.venv/lib/python3.10/site-packages/ray/tune/trainable/function_trainable.py", line 115, in <lambda>
    training_func=lambda: self._trainable_func(self.config),
  File "/data/gpfs/projects/punim1355/dalmiapriyam/predator-prey/.venv/lib/python3.10/site-packages/ray/tune/trainable/function_trainable.py", line 332, in _trainable_func
    output = fn()
  File "/data/gpfs/projects/punim1355/dalmiapriyam/predator-prey/./train.py", line 211, in train_algo
    wandb.init(
  File "/data/gpfs/projects/punim1355/dalmiapriyam/predator-prey/.venv/lib/python3.10/site-packages/wandb/sdk/wandb_init.py", line 1204, in init
    raise Error("An unexpected error occurred") from error_seen
wandb.errors.Error: An unexpected error occurred
2023-12-06 22:48:59,117	ERROR tune_controller.py:1383 -- Trial task failed for trial train_algo_64c6a_00029
Traceback (most recent call last):
  File "/data/gpfs/projects/punim1355/dalmiapriyam/predator-prey/.venv/lib/python3.10/site-packages/ray/air/execution/_internal/event_manager.py", line 110, in resolve_future
    result = ray.get(future)
  File "/data/gpfs/projects/punim1355/dalmiapriyam/predator-prey/.venv/lib/python3.10/site-packages/ray/_private/auto_init_hook.py", line 24, in auto_init_wrapper
    return fn(*args, **kwargs)
  File "/data/gpfs/projects/punim1355/dalmiapriyam/predator-prey/.venv/lib/python3.10/site-packages/ray/_private/client_mode_hook.py", line 103, in wrapper
    return func(*args, **kwargs)
  File "/data/gpfs/projects/punim1355/dalmiapriyam/predator-prey/.venv/lib/python3.10/site-packages/ray/_private/worker.py", line 2563, in get
    raise value.as_instanceof_cause()
ray.exceptions.RayTaskError(Error): [36mray::ImplicitFunc.train()[39m (pid=96913, ip=172.26.93.143, actor_id=077eb78b131c99aee092d7b601000000, repr=train_algo)
  File "/data/gpfs/projects/punim1355/dalmiapriyam/predator-prey/.venv/lib/python3.10/site-packages/wandb/sdk/wandb_init.py", line 189, in setup
    self._wl = wandb_setup.setup(settings=setup_settings)
  File "/data/gpfs/projects/punim1355/dalmiapriyam/predator-prey/.venv/lib/python3.10/site-packages/wandb/sdk/wandb_setup.py", line 327, in setup
    ret = _setup(settings=settings)
  File "/data/gpfs/projects/punim1355/dalmiapriyam/predator-prey/.venv/lib/python3.10/site-packages/wandb/sdk/wandb_setup.py", line 320, in _setup
    wl = _WandbSetup(settings=settings)
  File "/data/gpfs/projects/punim1355/dalmiapriyam/predator-prey/.venv/lib/python3.10/site-packages/wandb/sdk/wandb_setup.py", line 303, in __init__
    _WandbSetup._instance = _WandbSetup__WandbSetup(settings=settings, pid=pid)
  File "/data/gpfs/projects/punim1355/dalmiapriyam/predator-prey/.venv/lib/python3.10/site-packages/wandb/sdk/wandb_setup.py", line 114, in __init__
    self._setup()
  File "/data/gpfs/projects/punim1355/dalmiapriyam/predator-prey/.venv/lib/python3.10/site-packages/wandb/sdk/wandb_setup.py", line 250, in _setup
    self._setup_manager()
  File "/data/gpfs/projects/punim1355/dalmiapriyam/predator-prey/.venv/lib/python3.10/site-packages/wandb/sdk/wandb_setup.py", line 277, in _setup_manager
    self._manager = wandb_manager._Manager(settings=self._settings)
  File "/data/gpfs/projects/punim1355/dalmiapriyam/predator-prey/.venv/lib/python3.10/site-packages/wandb/sdk/wandb_manager.py", line 138, in __init__
    self._service.start()
  File "/data/gpfs/projects/punim1355/dalmiapriyam/predator-prey/.venv/lib/python3.10/site-packages/wandb/sdk/service/service.py", line 258, in start
    self._launch_server()
  File "/data/gpfs/projects/punim1355/dalmiapriyam/predator-prey/.venv/lib/python3.10/site-packages/wandb/sdk/service/service.py", line 164, in _launch_server
    with tempfile.TemporaryDirectory() as tmpdir:
  File "/apps/easybuild-2022/easybuild/software/Compiler/GCCcore/11.3.0/Python/3.10.4/lib/python3.10/tempfile.py", line 796, in __init__
    self.name = mkdtemp(suffix, prefix, dir)
  File "/apps/easybuild-2022/easybuild/software/Compiler/GCCcore/11.3.0/Python/3.10.4/lib/python3.10/tempfile.py", line 368, in mkdtemp
    _os.mkdir(file, 0o700)
FileNotFoundError: [Errno 2] No such file or directory: '/tmp/tmp6ovh6ue5'

The above exception was the direct cause of the following exception:

[36mray::ImplicitFunc.train()[39m (pid=96913, ip=172.26.93.143, actor_id=077eb78b131c99aee092d7b601000000, repr=train_algo)
  File "/data/gpfs/projects/punim1355/dalmiapriyam/predator-prey/.venv/lib/python3.10/site-packages/ray/tune/trainable/trainable.py", line 342, in train
    raise skipped from exception_cause(skipped)
  File "/data/gpfs/projects/punim1355/dalmiapriyam/predator-prey/.venv/lib/python3.10/site-packages/ray/air/_internal/util.py", line 91, in run
    self._ret = self._target(*self._args, **self._kwargs)
  File "/data/gpfs/projects/punim1355/dalmiapriyam/predator-prey/.venv/lib/python3.10/site-packages/ray/tune/trainable/function_trainable.py", line 115, in <lambda>
    training_func=lambda: self._trainable_func(self.config),
  File "/data/gpfs/projects/punim1355/dalmiapriyam/predator-prey/.venv/lib/python3.10/site-packages/ray/tune/trainable/function_trainable.py", line 332, in _trainable_func
    output = fn()
  File "/data/gpfs/projects/punim1355/dalmiapriyam/predator-prey/./train.py", line 211, in train_algo
    wandb.init(
  File "/data/gpfs/projects/punim1355/dalmiapriyam/predator-prey/.venv/lib/python3.10/site-packages/wandb/sdk/wandb_init.py", line 1204, in init
    raise Error("An unexpected error occurred") from error_seen
wandb.errors.Error: An unexpected error occurred
2023-12-06 22:48:59,127	ERROR tune_controller.py:1383 -- Trial task failed for trial train_algo_64c6a_00012
Traceback (most recent call last):
  File "/data/gpfs/projects/punim1355/dalmiapriyam/predator-prey/.venv/lib/python3.10/site-packages/ray/air/execution/_internal/event_manager.py", line 110, in resolve_future
    result = ray.get(future)
  File "/data/gpfs/projects/punim1355/dalmiapriyam/predator-prey/.venv/lib/python3.10/site-packages/ray/_private/auto_init_hook.py", line 24, in auto_init_wrapper
    return fn(*args, **kwargs)
  File "/data/gpfs/projects/punim1355/dalmiapriyam/predator-prey/.venv/lib/python3.10/site-packages/ray/_private/client_mode_hook.py", line 103, in wrapper
    return func(*args, **kwargs)
  File "/data/gpfs/projects/punim1355/dalmiapriyam/predator-prey/.venv/lib/python3.10/site-packages/ray/_private/worker.py", line 2563, in get
    raise value.as_instanceof_cause()
ray.exceptions.RayTaskError(Error): [36mray::ImplicitFunc.train()[39m (pid=96898, ip=172.26.93.143, actor_id=33a9c562a685f2a9c701925301000000, repr=train_algo)
  File "/data/gpfs/projects/punim1355/dalmiapriyam/predator-prey/.venv/lib/python3.10/site-packages/wandb/sdk/wandb_init.py", line 189, in setup
    self._wl = wandb_setup.setup(settings=setup_settings)
  File "/data/gpfs/projects/punim1355/dalmiapriyam/predator-prey/.venv/lib/python3.10/site-packages/wandb/sdk/wandb_setup.py", line 327, in setup
    ret = _setup(settings=settings)
  File "/data/gpfs/projects/punim1355/dalmiapriyam/predator-prey/.venv/lib/python3.10/site-packages/wandb/sdk/wandb_setup.py", line 320, in _setup
    wl = _WandbSetup(settings=settings)
  File "/data/gpfs/projects/punim1355/dalmiapriyam/predator-prey/.venv/lib/python3.10/site-packages/wandb/sdk/wandb_setup.py", line 303, in __init__
    _WandbSetup._instance = _WandbSetup__WandbSetup(settings=settings, pid=pid)
  File "/data/gpfs/projects/punim1355/dalmiapriyam/predator-prey/.venv/lib/python3.10/site-packages/wandb/sdk/wandb_setup.py", line 114, in __init__
    self._setup()
  File "/data/gpfs/projects/punim1355/dalmiapriyam/predator-prey/.venv/lib/python3.10/site-packages/wandb/sdk/wandb_setup.py", line 250, in _setup
    self._setup_manager()
  File "/data/gpfs/projects/punim1355/dalmiapriyam/predator-prey/.venv/lib/python3.10/site-packages/wandb/sdk/wandb_setup.py", line 277, in _setup_manager
    self._manager = wandb_manager._Manager(settings=self._settings)
  File "/data/gpfs/projects/punim1355/dalmiapriyam/predator-prey/.venv/lib/python3.10/site-packages/wandb/sdk/wandb_manager.py", line 138, in __init__
    self._service.start()
  File "/data/gpfs/projects/punim1355/dalmiapriyam/predator-prey/.venv/lib/python3.10/site-packages/wandb/sdk/service/service.py", line 258, in start
    self._launch_server()
  File "/data/gpfs/projects/punim1355/dalmiapriyam/predator-prey/.venv/lib/python3.10/site-packages/wandb/sdk/service/service.py", line 164, in _launch_server
    with tempfile.TemporaryDirectory() as tmpdir:
  File "/apps/easybuild-2022/easybuild/software/Compiler/GCCcore/11.3.0/Python/3.10.4/lib/python3.10/tempfile.py", line 796, in __init__
    self.name = mkdtemp(suffix, prefix, dir)
  File "/apps/easybuild-2022/easybuild/software/Compiler/GCCcore/11.3.0/Python/3.10.4/lib/python3.10/tempfile.py", line 368, in mkdtemp
    _os.mkdir(file, 0o700)
FileNotFoundError: [Errno 2] No such file or directory: '/tmp/tmp08ptevt5'

The above exception was the direct cause of the following exception:

[36mray::ImplicitFunc.train()[39m (pid=96898, ip=172.26.93.143, actor_id=33a9c562a685f2a9c701925301000000, repr=train_algo)
  File "/data/gpfs/projects/punim1355/dalmiapriyam/predator-prey/.venv/lib/python3.10/site-packages/ray/tune/trainable/trainable.py", line 342, in train
    raise skipped from exception_cause(skipped)
  File "/data/gpfs/projects/punim1355/dalmiapriyam/predator-prey/.venv/lib/python3.10/site-packages/ray/air/_internal/util.py", line 91, in run
    self._ret = self._target(*self._args, **self._kwargs)
  File "/data/gpfs/projects/punim1355/dalmiapriyam/predator-prey/.venv/lib/python3.10/site-packages/ray/tune/trainable/function_trainable.py", line 115, in <lambda>
    training_func=lambda: self._trainable_func(self.config),
  File "/data/gpfs/projects/punim1355/dalmiapriyam/predator-prey/.venv/lib/python3.10/site-packages/ray/tune/trainable/function_trainable.py", line 332, in _trainable_func
    output = fn()
  File "/data/gpfs/projects/punim1355/dalmiapriyam/predator-prey/./train.py", line 211, in train_algo
    wandb.init(
  File "/data/gpfs/projects/punim1355/dalmiapriyam/predator-prey/.venv/lib/python3.10/site-packages/wandb/sdk/wandb_init.py", line 1204, in init
    raise Error("An unexpected error occurred") from error_seen
wandb.errors.Error: An unexpected error occurred
2023-12-06 22:48:59,138	ERROR tune_controller.py:1383 -- Trial task failed for trial train_algo_64c6a_00007
Traceback (most recent call last):
  File "/data/gpfs/projects/punim1355/dalmiapriyam/predator-prey/.venv/lib/python3.10/site-packages/ray/air/execution/_internal/event_manager.py", line 110, in resolve_future
    result = ray.get(future)
  File "/data/gpfs/projects/punim1355/dalmiapriyam/predator-prey/.venv/lib/python3.10/site-packages/ray/_private/auto_init_hook.py", line 24, in auto_init_wrapper
    return fn(*args, **kwargs)
  File "/data/gpfs/projects/punim1355/dalmiapriyam/predator-prey/.venv/lib/python3.10/site-packages/ray/_private/client_mode_hook.py", line 103, in wrapper
    return func(*args, **kwargs)
  File "/data/gpfs/projects/punim1355/dalmiapriyam/predator-prey/.venv/lib/python3.10/site-packages/ray/_private/worker.py", line 2563, in get
    raise value.as_instanceof_cause()
ray.exceptions.RayTaskError(Error): [36mray::ImplicitFunc.train()[39m (pid=96891, ip=172.26.93.143, actor_id=867ea86c61c14d320a01961c01000000, repr=train_algo)
  File "/data/gpfs/projects/punim1355/dalmiapriyam/predator-prey/.venv/lib/python3.10/site-packages/wandb/sdk/wandb_init.py", line 189, in setup
    self._wl = wandb_setup.setup(settings=setup_settings)
  File "/data/gpfs/projects/punim1355/dalmiapriyam/predator-prey/.venv/lib/python3.10/site-packages/wandb/sdk/wandb_setup.py", line 327, in setup
    ret = _setup(settings=settings)
  File "/data/gpfs/projects/punim1355/dalmiapriyam/predator-prey/.venv/lib/python3.10/site-packages/wandb/sdk/wandb_setup.py", line 320, in _setup
    wl = _WandbSetup(settings=settings)
  File "/data/gpfs/projects/punim1355/dalmiapriyam/predator-prey/.venv/lib/python3.10/site-packages/wandb/sdk/wandb_setup.py", line 303, in __init__
    _WandbSetup._instance = _WandbSetup__WandbSetup(settings=settings, pid=pid)
  File "/data/gpfs/projects/punim1355/dalmiapriyam/predator-prey/.venv/lib/python3.10/site-packages/wandb/sdk/wandb_setup.py", line 114, in __init__
    self._setup()
  File "/data/gpfs/projects/punim1355/dalmiapriyam/predator-prey/.venv/lib/python3.10/site-packages/wandb/sdk/wandb_setup.py", line 250, in _setup
    self._setup_manager()
  File "/data/gpfs/projects/punim1355/dalmiapriyam/predator-prey/.venv/lib/python3.10/site-packages/wandb/sdk/wandb_setup.py", line 277, in _setup_manager
    self._manager = wandb_manager._Manager(settings=self._settings)
  File "/data/gpfs/projects/punim1355/dalmiapriyam/predator-prey/.venv/lib/python3.10/site-packages/wandb/sdk/wandb_manager.py", line 138, in __init__
    self._service.start()
  File "/data/gpfs/projects/punim1355/dalmiapriyam/predator-prey/.venv/lib/python3.10/site-packages/wandb/sdk/service/service.py", line 258, in start
    self._launch_server()
  File "/data/gpfs/projects/punim1355/dalmiapriyam/predator-prey/.venv/lib/python3.10/site-packages/wandb/sdk/service/service.py", line 164, in _launch_server
    with tempfile.TemporaryDirectory() as tmpdir:
  File "/apps/easybuild-2022/easybuild/software/Compiler/GCCcore/11.3.0/Python/3.10.4/lib/python3.10/tempfile.py", line 796, in __init__
    self.name = mkdtemp(suffix, prefix, dir)
  File "/apps/easybuild-2022/easybuild/software/Compiler/GCCcore/11.3.0/Python/3.10.4/lib/python3.10/tempfile.py", line 368, in mkdtemp
    _os.mkdir(file, 0o700)
FileNotFoundError: [Errno 2] No such file or directory: '/tmp/tmpfn7vujih'

The above exception was the direct cause of the following exception:

[36mray::ImplicitFunc.train()[39m (pid=96891, ip=172.26.93.143, actor_id=867ea86c61c14d320a01961c01000000, repr=train_algo)
  File "/data/gpfs/projects/punim1355/dalmiapriyam/predator-prey/.venv/lib/python3.10/site-packages/ray/tune/trainable/trainable.py", line 342, in train
    raise skipped from exception_cause(skipped)
  File "/data/gpfs/projects/punim1355/dalmiapriyam/predator-prey/.venv/lib/python3.10/site-packages/ray/air/_internal/util.py", line 91, in run
    self._ret = self._target(*self._args, **self._kwargs)
  File "/data/gpfs/projects/punim1355/dalmiapriyam/predator-prey/.venv/lib/python3.10/site-packages/ray/tune/trainable/function_trainable.py", line 115, in <lambda>
    training_func=lambda: self._trainable_func(self.config),
  File "/data/gpfs/projects/punim1355/dalmiapriyam/predator-prey/.venv/lib/python3.10/site-packages/ray/tune/trainable/function_trainable.py", line 332, in _trainable_func
    output = fn()
  File "/data/gpfs/projects/punim1355/dalmiapriyam/predator-prey/./train.py", line 211, in train_algo
    wandb.init(
  File "/data/gpfs/projects/punim1355/dalmiapriyam/predator-prey/.venv/lib/python3.10/site-packages/wandb/sdk/wandb_init.py", line 1204, in init
    raise Error("An unexpected error occurred") from error_seen
wandb.errors.Error: An unexpected error occurred
2023-12-06 22:48:59,149	ERROR tune_controller.py:1383 -- Trial task failed for trial train_algo_64c6a_00017
Traceback (most recent call last):
  File "/data/gpfs/projects/punim1355/dalmiapriyam/predator-prey/.venv/lib/python3.10/site-packages/ray/air/execution/_internal/event_manager.py", line 110, in resolve_future
    result = ray.get(future)
  File "/data/gpfs/projects/punim1355/dalmiapriyam/predator-prey/.venv/lib/python3.10/site-packages/ray/_private/auto_init_hook.py", line 24, in auto_init_wrapper
    return fn(*args, **kwargs)
  File "/data/gpfs/projects/punim1355/dalmiapriyam/predator-prey/.venv/lib/python3.10/site-packages/ray/_private/client_mode_hook.py", line 103, in wrapper
    return func(*args, **kwargs)
  File "/data/gpfs/projects/punim1355/dalmiapriyam/predator-prey/.venv/lib/python3.10/site-packages/ray/_private/worker.py", line 2563, in get
    raise value.as_instanceof_cause()
ray.exceptions.RayTaskError(Error): [36mray::ImplicitFunc.train()[39m (pid=96903, ip=172.26.93.143, actor_id=aa8dbbafbb5ec7edafb4512401000000, repr=train_algo)
  File "/data/gpfs/projects/punim1355/dalmiapriyam/predator-prey/.venv/lib/python3.10/site-packages/wandb/sdk/wandb_init.py", line 189, in setup
    self._wl = wandb_setup.setup(settings=setup_settings)
  File "/data/gpfs/projects/punim1355/dalmiapriyam/predator-prey/.venv/lib/python3.10/site-packages/wandb/sdk/wandb_setup.py", line 327, in setup
    ret = _setup(settings=settings)
  File "/data/gpfs/projects/punim1355/dalmiapriyam/predator-prey/.venv/lib/python3.10/site-packages/wandb/sdk/wandb_setup.py", line 320, in _setup
    wl = _WandbSetup(settings=settings)
  File "/data/gpfs/projects/punim1355/dalmiapriyam/predator-prey/.venv/lib/python3.10/site-packages/wandb/sdk/wandb_setup.py", line 303, in __init__
    _WandbSetup._instance = _WandbSetup__WandbSetup(settings=settings, pid=pid)
  File "/data/gpfs/projects/punim1355/dalmiapriyam/predator-prey/.venv/lib/python3.10/site-packages/wandb/sdk/wandb_setup.py", line 114, in __init__
    self._setup()
  File "/data/gpfs/projects/punim1355/dalmiapriyam/predator-prey/.venv/lib/python3.10/site-packages/wandb/sdk/wandb_setup.py", line 250, in _setup
    self._setup_manager()
  File "/data/gpfs/projects/punim1355/dalmiapriyam/predator-prey/.venv/lib/python3.10/site-packages/wandb/sdk/wandb_setup.py", line 277, in _setup_manager
    self._manager = wandb_manager._Manager(settings=self._settings)
  File "/data/gpfs/projects/punim1355/dalmiapriyam/predator-prey/.venv/lib/python3.10/site-packages/wandb/sdk/wandb_manager.py", line 138, in __init__
    self._service.start()
  File "/data/gpfs/projects/punim1355/dalmiapriyam/predator-prey/.venv/lib/python3.10/site-packages/wandb/sdk/service/service.py", line 258, in start
    self._launch_server()
  File "/data/gpfs/projects/punim1355/dalmiapriyam/predator-prey/.venv/lib/python3.10/site-packages/wandb/sdk/service/service.py", line 164, in _launch_server
    with tempfile.TemporaryDirectory() as tmpdir:
  File "/apps/easybuild-2022/easybuild/software/Compiler/GCCcore/11.3.0/Python/3.10.4/lib/python3.10/tempfile.py", line 796, in __init__
    self.name = mkdtemp(suffix, prefix, dir)
  File "/apps/easybuild-2022/easybuild/software/Compiler/GCCcore/11.3.0/Python/3.10.4/lib/python3.10/tempfile.py", line 368, in mkdtemp
    _os.mkdir(file, 0o700)
FileNotFoundError: [Errno 2] No such file or directory: '/tmp/tmp7807887v'

The above exception was the direct cause of the following exception:

[36mray::ImplicitFunc.train()[39m (pid=96903, ip=172.26.93.143, actor_id=aa8dbbafbb5ec7edafb4512401000000, repr=train_algo)
  File "/data/gpfs/projects/punim1355/dalmiapriyam/predator-prey/.venv/lib/python3.10/site-packages/ray/tune/trainable/trainable.py", line 342, in train
    raise skipped from exception_cause(skipped)
  File "/data/gpfs/projects/punim1355/dalmiapriyam/predator-prey/.venv/lib/python3.10/site-packages/ray/air/_internal/util.py", line 91, in run
    self._ret = self._target(*self._args, **self._kwargs)
  File "/data/gpfs/projects/punim1355/dalmiapriyam/predator-prey/.venv/lib/python3.10/site-packages/ray/tune/trainable/function_trainable.py", line 115, in <lambda>
    training_func=lambda: self._trainable_func(self.config),
  File "/data/gpfs/projects/punim1355/dalmiapriyam/predator-prey/.venv/lib/python3.10/site-packages/ray/tune/trainable/function_trainable.py", line 332, in _trainable_func
    output = fn()
  File "/data/gpfs/projects/punim1355/dalmiapriyam/predator-prey/./train.py", line 211, in train_algo
    wandb.init(
  File "/data/gpfs/projects/punim1355/dalmiapriyam/predator-prey/.venv/lib/python3.10/site-packages/wandb/sdk/wandb_init.py", line 1204, in init
    raise Error("An unexpected error occurred") from error_seen
wandb.errors.Error: An unexpected error occurred
2023-12-06 22:48:59,162	ERROR tune_controller.py:1383 -- Trial task failed for trial train_algo_64c6a_00008
Traceback (most recent call last):
  File "/data/gpfs/projects/punim1355/dalmiapriyam/predator-prey/.venv/lib/python3.10/site-packages/ray/air/execution/_internal/event_manager.py", line 110, in resolve_future
    result = ray.get(future)
  File "/data/gpfs/projects/punim1355/dalmiapriyam/predator-prey/.venv/lib/python3.10/site-packages/ray/_private/auto_init_hook.py", line 24, in auto_init_wrapper
    return fn(*args, **kwargs)
  File "/data/gpfs/projects/punim1355/dalmiapriyam/predator-prey/.venv/lib/python3.10/site-packages/ray/_private/client_mode_hook.py", line 103, in wrapper
    return func(*args, **kwargs)
  File "/data/gpfs/projects/punim1355/dalmiapriyam/predator-prey/.venv/lib/python3.10/site-packages/ray/_private/worker.py", line 2563, in get
    raise value.as_instanceof_cause()
ray.exceptions.RayTaskError(Error): [36mray::ImplicitFunc.train()[39m (pid=96894, ip=172.26.93.143, actor_id=0ee6a67f79bb8f037e3c94dd01000000, repr=train_algo)
  File "/data/gpfs/projects/punim1355/dalmiapriyam/predator-prey/.venv/lib/python3.10/site-packages/wandb/sdk/wandb_init.py", line 189, in setup
    self._wl = wandb_setup.setup(settings=setup_settings)
  File "/data/gpfs/projects/punim1355/dalmiapriyam/predator-prey/.venv/lib/python3.10/site-packages/wandb/sdk/wandb_setup.py", line 327, in setup
    ret = _setup(settings=settings)
  File "/data/gpfs/projects/punim1355/dalmiapriyam/predator-prey/.venv/lib/python3.10/site-packages/wandb/sdk/wandb_setup.py", line 320, in _setup
    wl = _WandbSetup(settings=settings)
  File "/data/gpfs/projects/punim1355/dalmiapriyam/predator-prey/.venv/lib/python3.10/site-packages/wandb/sdk/wandb_setup.py", line 303, in __init__
    _WandbSetup._instance = _WandbSetup__WandbSetup(settings=settings, pid=pid)
  File "/data/gpfs/projects/punim1355/dalmiapriyam/predator-prey/.venv/lib/python3.10/site-packages/wandb/sdk/wandb_setup.py", line 114, in __init__
    self._setup()
  File "/data/gpfs/projects/punim1355/dalmiapriyam/predator-prey/.venv/lib/python3.10/site-packages/wandb/sdk/wandb_setup.py", line 250, in _setup
    self._setup_manager()
  File "/data/gpfs/projects/punim1355/dalmiapriyam/predator-prey/.venv/lib/python3.10/site-packages/wandb/sdk/wandb_setup.py", line 277, in _setup_manager
    self._manager = wandb_manager._Manager(settings=self._settings)
  File "/data/gpfs/projects/punim1355/dalmiapriyam/predator-prey/.venv/lib/python3.10/site-packages/wandb/sdk/wandb_manager.py", line 138, in __init__
    self._service.start()
  File "/data/gpfs/projects/punim1355/dalmiapriyam/predator-prey/.venv/lib/python3.10/site-packages/wandb/sdk/service/service.py", line 258, in start
    self._launch_server()
  File "/data/gpfs/projects/punim1355/dalmiapriyam/predator-prey/.venv/lib/python3.10/site-packages/wandb/sdk/service/service.py", line 164, in _launch_server
    with tempfile.TemporaryDirectory() as tmpdir:
  File "/apps/easybuild-2022/easybuild/software/Compiler/GCCcore/11.3.0/Python/3.10.4/lib/python3.10/tempfile.py", line 796, in __init__
    self.name = mkdtemp(suffix, prefix, dir)
  File "/apps/easybuild-2022/easybuild/software/Compiler/GCCcore/11.3.0/Python/3.10.4/lib/python3.10/tempfile.py", line 368, in mkdtemp
    _os.mkdir(file, 0o700)
FileNotFoundError: [Errno 2] No such file or directory: '/tmp/tmp3i1n_w4a'

The above exception was the direct cause of the following exception:

[36mray::ImplicitFunc.train()[39m (pid=96894, ip=172.26.93.143, actor_id=0ee6a67f79bb8f037e3c94dd01000000, repr=train_algo)
  File "/data/gpfs/projects/punim1355/dalmiapriyam/predator-prey/.venv/lib/python3.10/site-packages/ray/tune/trainable/trainable.py", line 342, in train
    raise skipped from exception_cause(skipped)
  File "/data/gpfs/projects/punim1355/dalmiapriyam/predator-prey/.venv/lib/python3.10/site-packages/ray/air/_internal/util.py", line 91, in run
    self._ret = self._target(*self._args, **self._kwargs)
  File "/data/gpfs/projects/punim1355/dalmiapriyam/predator-prey/.venv/lib/python3.10/site-packages/ray/tune/trainable/function_trainable.py", line 115, in <lambda>
    training_func=lambda: self._trainable_func(self.config),
  File "/data/gpfs/projects/punim1355/dalmiapriyam/predator-prey/.venv/lib/python3.10/site-packages/ray/tune/trainable/function_trainable.py", line 332, in _trainable_func
    output = fn()
  File "/data/gpfs/projects/punim1355/dalmiapriyam/predator-prey/./train.py", line 211, in train_algo
    wandb.init(
  File "/data/gpfs/projects/punim1355/dalmiapriyam/predator-prey/.venv/lib/python3.10/site-packages/wandb/sdk/wandb_init.py", line 1204, in init
    raise Error("An unexpected error occurred") from error_seen
wandb.errors.Error: An unexpected error occurred
2023-12-06 22:48:59,173	ERROR tune_controller.py:1383 -- Trial task failed for trial train_algo_64c6a_00027
Traceback (most recent call last):
  File "/data/gpfs/projects/punim1355/dalmiapriyam/predator-prey/.venv/lib/python3.10/site-packages/ray/air/execution/_internal/event_manager.py", line 110, in resolve_future
    result = ray.get(future)
  File "/data/gpfs/projects/punim1355/dalmiapriyam/predator-prey/.venv/lib/python3.10/site-packages/ray/_private/auto_init_hook.py", line 24, in auto_init_wrapper
    return fn(*args, **kwargs)
  File "/data/gpfs/projects/punim1355/dalmiapriyam/predator-prey/.venv/lib/python3.10/site-packages/ray/_private/client_mode_hook.py", line 103, in wrapper
    return func(*args, **kwargs)
  File "/data/gpfs/projects/punim1355/dalmiapriyam/predator-prey/.venv/lib/python3.10/site-packages/ray/_private/worker.py", line 2563, in get
    raise value.as_instanceof_cause()
ray.exceptions.RayTaskError(Error): [36mray::ImplicitFunc.train()[39m (pid=96915, ip=172.26.93.143, actor_id=4830bd368f1d99a276751e4601000000, repr=train_algo)
  File "/data/gpfs/projects/punim1355/dalmiapriyam/predator-prey/.venv/lib/python3.10/site-packages/wandb/sdk/wandb_init.py", line 189, in setup
    self._wl = wandb_setup.setup(settings=setup_settings)
  File "/data/gpfs/projects/punim1355/dalmiapriyam/predator-prey/.venv/lib/python3.10/site-packages/wandb/sdk/wandb_setup.py", line 327, in setup
    ret = _setup(settings=settings)
  File "/data/gpfs/projects/punim1355/dalmiapriyam/predator-prey/.venv/lib/python3.10/site-packages/wandb/sdk/wandb_setup.py", line 320, in _setup
    wl = _WandbSetup(settings=settings)
  File "/data/gpfs/projects/punim1355/dalmiapriyam/predator-prey/.venv/lib/python3.10/site-packages/wandb/sdk/wandb_setup.py", line 303, in __init__
    _WandbSetup._instance = _WandbSetup__WandbSetup(settings=settings, pid=pid)
  File "/data/gpfs/projects/punim1355/dalmiapriyam/predator-prey/.venv/lib/python3.10/site-packages/wandb/sdk/wandb_setup.py", line 114, in __init__
    self._setup()
  File "/data/gpfs/projects/punim1355/dalmiapriyam/predator-prey/.venv/lib/python3.10/site-packages/wandb/sdk/wandb_setup.py", line 250, in _setup
    self._setup_manager()
  File "/data/gpfs/projects/punim1355/dalmiapriyam/predator-prey/.venv/lib/python3.10/site-packages/wandb/sdk/wandb_setup.py", line 277, in _setup_manager
    self._manager = wandb_manager._Manager(settings=self._settings)
  File "/data/gpfs/projects/punim1355/dalmiapriyam/predator-prey/.venv/lib/python3.10/site-packages/wandb/sdk/wandb_manager.py", line 138, in __init__
    self._service.start()
  File "/data/gpfs/projects/punim1355/dalmiapriyam/predator-prey/.venv/lib/python3.10/site-packages/wandb/sdk/service/service.py", line 258, in start
    self._launch_server()
  File "/data/gpfs/projects/punim1355/dalmiapriyam/predator-prey/.venv/lib/python3.10/site-packages/wandb/sdk/service/service.py", line 164, in _launch_server
    with tempfile.TemporaryDirectory() as tmpdir:
  File "/apps/easybuild-2022/easybuild/software/Compiler/GCCcore/11.3.0/Python/3.10.4/lib/python3.10/tempfile.py", line 796, in __init__
    self.name = mkdtemp(suffix, prefix, dir)
  File "/apps/easybuild-2022/easybuild/software/Compiler/GCCcore/11.3.0/Python/3.10.4/lib/python3.10/tempfile.py", line 368, in mkdtemp
    _os.mkdir(file, 0o700)
FileNotFoundError: [Errno 2] No such file or directory: '/tmp/tmptlf0p16p'

The above exception was the direct cause of the following exception:

[36mray::ImplicitFunc.train()[39m (pid=96915, ip=172.26.93.143, actor_id=4830bd368f1d99a276751e4601000000, repr=train_algo)
  File "/data/gpfs/projects/punim1355/dalmiapriyam/predator-prey/.venv/lib/python3.10/site-packages/ray/tune/trainable/trainable.py", line 342, in train
    raise skipped from exception_cause(skipped)
  File "/data/gpfs/projects/punim1355/dalmiapriyam/predator-prey/.venv/lib/python3.10/site-packages/ray/air/_internal/util.py", line 91, in run
    self._ret = self._target(*self._args, **self._kwargs)
  File "/data/gpfs/projects/punim1355/dalmiapriyam/predator-prey/.venv/lib/python3.10/site-packages/ray/tune/trainable/function_trainable.py", line 115, in <lambda>
    training_func=lambda: self._trainable_func(self.config),
  File "/data/gpfs/projects/punim1355/dalmiapriyam/predator-prey/.venv/lib/python3.10/site-packages/ray/tune/trainable/function_trainable.py", line 332, in _trainable_func
    output = fn()
  File "/data/gpfs/projects/punim1355/dalmiapriyam/predator-prey/./train.py", line 211, in train_algo
    wandb.init(
  File "/data/gpfs/projects/punim1355/dalmiapriyam/predator-prey/.venv/lib/python3.10/site-packages/wandb/sdk/wandb_init.py", line 1204, in init
    raise Error("An unexpected error occurred") from error_seen
wandb.errors.Error: An unexpected error occurred
2023-12-06 22:48:59,184	ERROR tune_controller.py:1383 -- Trial task failed for trial train_algo_64c6a_00031
Traceback (most recent call last):
  File "/data/gpfs/projects/punim1355/dalmiapriyam/predator-prey/.venv/lib/python3.10/site-packages/ray/air/execution/_internal/event_manager.py", line 110, in resolve_future
    result = ray.get(future)
  File "/data/gpfs/projects/punim1355/dalmiapriyam/predator-prey/.venv/lib/python3.10/site-packages/ray/_private/auto_init_hook.py", line 24, in auto_init_wrapper
    return fn(*args, **kwargs)
  File "/data/gpfs/projects/punim1355/dalmiapriyam/predator-prey/.venv/lib/python3.10/site-packages/ray/_private/client_mode_hook.py", line 103, in wrapper
    return func(*args, **kwargs)
  File "/data/gpfs/projects/punim1355/dalmiapriyam/predator-prey/.venv/lib/python3.10/site-packages/ray/_private/worker.py", line 2563, in get
    raise value.as_instanceof_cause()
ray.exceptions.RayTaskError(Error): [36mray::ImplicitFunc.train()[39m (pid=96917, ip=172.26.93.143, actor_id=aa4a743340a746870bbeec3f01000000, repr=train_algo)
  File "/data/gpfs/projects/punim1355/dalmiapriyam/predator-prey/.venv/lib/python3.10/site-packages/wandb/sdk/wandb_init.py", line 189, in setup
    self._wl = wandb_setup.setup(settings=setup_settings)
  File "/data/gpfs/projects/punim1355/dalmiapriyam/predator-prey/.venv/lib/python3.10/site-packages/wandb/sdk/wandb_setup.py", line 327, in setup
    ret = _setup(settings=settings)
  File "/data/gpfs/projects/punim1355/dalmiapriyam/predator-prey/.venv/lib/python3.10/site-packages/wandb/sdk/wandb_setup.py", line 320, in _setup
    wl = _WandbSetup(settings=settings)
  File "/data/gpfs/projects/punim1355/dalmiapriyam/predator-prey/.venv/lib/python3.10/site-packages/wandb/sdk/wandb_setup.py", line 303, in __init__
    _WandbSetup._instance = _WandbSetup__WandbSetup(settings=settings, pid=pid)
  File "/data/gpfs/projects/punim1355/dalmiapriyam/predator-prey/.venv/lib/python3.10/site-packages/wandb/sdk/wandb_setup.py", line 114, in __init__
    self._setup()
  File "/data/gpfs/projects/punim1355/dalmiapriyam/predator-prey/.venv/lib/python3.10/site-packages/wandb/sdk/wandb_setup.py", line 250, in _setup
    self._setup_manager()
  File "/data/gpfs/projects/punim1355/dalmiapriyam/predator-prey/.venv/lib/python3.10/site-packages/wandb/sdk/wandb_setup.py", line 277, in _setup_manager
    self._manager = wandb_manager._Manager(settings=self._settings)
  File "/data/gpfs/projects/punim1355/dalmiapriyam/predator-prey/.venv/lib/python3.10/site-packages/wandb/sdk/wandb_manager.py", line 138, in __init__
    self._service.start()
  File "/data/gpfs/projects/punim1355/dalmiapriyam/predator-prey/.venv/lib/python3.10/site-packages/wandb/sdk/service/service.py", line 258, in start
    self._launch_server()
  File "/data/gpfs/projects/punim1355/dalmiapriyam/predator-prey/.venv/lib/python3.10/site-packages/wandb/sdk/service/service.py", line 164, in _launch_server
    with tempfile.TemporaryDirectory() as tmpdir:
  File "/apps/easybuild-2022/easybuild/software/Compiler/GCCcore/11.3.0/Python/3.10.4/lib/python3.10/tempfile.py", line 796, in __init__
    self.name = mkdtemp(suffix, prefix, dir)
  File "/apps/easybuild-2022/easybuild/software/Compiler/GCCcore/11.3.0/Python/3.10.4/lib/python3.10/tempfile.py", line 368, in mkdtemp
    _os.mkdir(file, 0o700)
FileNotFoundError: [Errno 2] No such file or directory: '/tmp/tmphk37jju5'

The above exception was the direct cause of the following exception:

[36mray::ImplicitFunc.train()[39m (pid=96917, ip=172.26.93.143, actor_id=aa4a743340a746870bbeec3f01000000, repr=train_algo)
  File "/data/gpfs/projects/punim1355/dalmiapriyam/predator-prey/.venv/lib/python3.10/site-packages/ray/tune/trainable/trainable.py", line 342, in train
    raise skipped from exception_cause(skipped)
  File "/data/gpfs/projects/punim1355/dalmiapriyam/predator-prey/.venv/lib/python3.10/site-packages/ray/air/_internal/util.py", line 91, in run
    self._ret = self._target(*self._args, **self._kwargs)
  File "/data/gpfs/projects/punim1355/dalmiapriyam/predator-prey/.venv/lib/python3.10/site-packages/ray/tune/trainable/function_trainable.py", line 115, in <lambda>
    training_func=lambda: self._trainable_func(self.config),
  File "/data/gpfs/projects/punim1355/dalmiapriyam/predator-prey/.venv/lib/python3.10/site-packages/ray/tune/trainable/function_trainable.py", line 332, in _trainable_func
    output = fn()
  File "/data/gpfs/projects/punim1355/dalmiapriyam/predator-prey/./train.py", line 211, in train_algo
    wandb.init(
  File "/data/gpfs/projects/punim1355/dalmiapriyam/predator-prey/.venv/lib/python3.10/site-packages/wandb/sdk/wandb_init.py", line 1204, in init
    raise Error("An unexpected error occurred") from error_seen
wandb.errors.Error: An unexpected error occurred
2023-12-06 22:48:59,194	ERROR tune_controller.py:1383 -- Trial task failed for trial train_algo_64c6a_00011
Traceback (most recent call last):
  File "/data/gpfs/projects/punim1355/dalmiapriyam/predator-prey/.venv/lib/python3.10/site-packages/ray/air/execution/_internal/event_manager.py", line 110, in resolve_future
    result = ray.get(future)
  File "/data/gpfs/projects/punim1355/dalmiapriyam/predator-prey/.venv/lib/python3.10/site-packages/ray/_private/auto_init_hook.py", line 24, in auto_init_wrapper
    return fn(*args, **kwargs)
  File "/data/gpfs/projects/punim1355/dalmiapriyam/predator-prey/.venv/lib/python3.10/site-packages/ray/_private/client_mode_hook.py", line 103, in wrapper
    return func(*args, **kwargs)
  File "/data/gpfs/projects/punim1355/dalmiapriyam/predator-prey/.venv/lib/python3.10/site-packages/ray/_private/worker.py", line 2563, in get
    raise value.as_instanceof_cause()
ray.exceptions.RayTaskError(Error): [36mray::ImplicitFunc.train()[39m (pid=96897, ip=172.26.93.143, actor_id=6e28078700f3c13c60f8de9501000000, repr=train_algo)
  File "/data/gpfs/projects/punim1355/dalmiapriyam/predator-prey/.venv/lib/python3.10/site-packages/wandb/sdk/wandb_init.py", line 189, in setup
    self._wl = wandb_setup.setup(settings=setup_settings)
  File "/data/gpfs/projects/punim1355/dalmiapriyam/predator-prey/.venv/lib/python3.10/site-packages/wandb/sdk/wandb_setup.py", line 327, in setup
    ret = _setup(settings=settings)
  File "/data/gpfs/projects/punim1355/dalmiapriyam/predator-prey/.venv/lib/python3.10/site-packages/wandb/sdk/wandb_setup.py", line 320, in _setup
    wl = _WandbSetup(settings=settings)
  File "/data/gpfs/projects/punim1355/dalmiapriyam/predator-prey/.venv/lib/python3.10/site-packages/wandb/sdk/wandb_setup.py", line 303, in __init__
    _WandbSetup._instance = _WandbSetup__WandbSetup(settings=settings, pid=pid)
  File "/data/gpfs/projects/punim1355/dalmiapriyam/predator-prey/.venv/lib/python3.10/site-packages/wandb/sdk/wandb_setup.py", line 114, in __init__
    self._setup()
  File "/data/gpfs/projects/punim1355/dalmiapriyam/predator-prey/.venv/lib/python3.10/site-packages/wandb/sdk/wandb_setup.py", line 250, in _setup
    self._setup_manager()
  File "/data/gpfs/projects/punim1355/dalmiapriyam/predator-prey/.venv/lib/python3.10/site-packages/wandb/sdk/wandb_setup.py", line 277, in _setup_manager
    self._manager = wandb_manager._Manager(settings=self._settings)
  File "/data/gpfs/projects/punim1355/dalmiapriyam/predator-prey/.venv/lib/python3.10/site-packages/wandb/sdk/wandb_manager.py", line 138, in __init__
    self._service.start()
  File "/data/gpfs/projects/punim1355/dalmiapriyam/predator-prey/.venv/lib/python3.10/site-packages/wandb/sdk/service/service.py", line 258, in start
    self._launch_server()
  File "/data/gpfs/projects/punim1355/dalmiapriyam/predator-prey/.venv/lib/python3.10/site-packages/wandb/sdk/service/service.py", line 164, in _launch_server
    with tempfile.TemporaryDirectory() as tmpdir:
  File "/apps/easybuild-2022/easybuild/software/Compiler/GCCcore/11.3.0/Python/3.10.4/lib/python3.10/tempfile.py", line 796, in __init__
    self.name = mkdtemp(suffix, prefix, dir)
  File "/apps/easybuild-2022/easybuild/software/Compiler/GCCcore/11.3.0/Python/3.10.4/lib/python3.10/tempfile.py", line 368, in mkdtemp
    _os.mkdir(file, 0o700)
FileNotFoundError: [Errno 2] No such file or directory: '/tmp/tmpkj8kjeeo'

The above exception was the direct cause of the following exception:

[36mray::ImplicitFunc.train()[39m (pid=96897, ip=172.26.93.143, actor_id=6e28078700f3c13c60f8de9501000000, repr=train_algo)
  File "/data/gpfs/projects/punim1355/dalmiapriyam/predator-prey/.venv/lib/python3.10/site-packages/ray/tune/trainable/trainable.py", line 342, in train
    raise skipped from exception_cause(skipped)
  File "/data/gpfs/projects/punim1355/dalmiapriyam/predator-prey/.venv/lib/python3.10/site-packages/ray/air/_internal/util.py", line 91, in run
    self._ret = self._target(*self._args, **self._kwargs)
  File "/data/gpfs/projects/punim1355/dalmiapriyam/predator-prey/.venv/lib/python3.10/site-packages/ray/tune/trainable/function_trainable.py", line 115, in <lambda>
    training_func=lambda: self._trainable_func(self.config),
  File "/data/gpfs/projects/punim1355/dalmiapriyam/predator-prey/.venv/lib/python3.10/site-packages/ray/tune/trainable/function_trainable.py", line 332, in _trainable_func
    output = fn()
  File "/data/gpfs/projects/punim1355/dalmiapriyam/predator-prey/./train.py", line 211, in train_algo
    wandb.init(
  File "/data/gpfs/projects/punim1355/dalmiapriyam/predator-prey/.venv/lib/python3.10/site-packages/wandb/sdk/wandb_init.py", line 1204, in init
    raise Error("An unexpected error occurred") from error_seen
wandb.errors.Error: An unexpected error occurred
2023-12-06 22:48:59,206	ERROR tune_controller.py:1383 -- Trial task failed for trial train_algo_64c6a_00028
Traceback (most recent call last):
  File "/data/gpfs/projects/punim1355/dalmiapriyam/predator-prey/.venv/lib/python3.10/site-packages/ray/air/execution/_internal/event_manager.py", line 110, in resolve_future
    result = ray.get(future)
  File "/data/gpfs/projects/punim1355/dalmiapriyam/predator-prey/.venv/lib/python3.10/site-packages/ray/_private/auto_init_hook.py", line 24, in auto_init_wrapper
    return fn(*args, **kwargs)
  File "/data/gpfs/projects/punim1355/dalmiapriyam/predator-prey/.venv/lib/python3.10/site-packages/ray/_private/client_mode_hook.py", line 103, in wrapper
    return func(*args, **kwargs)
  File "/data/gpfs/projects/punim1355/dalmiapriyam/predator-prey/.venv/lib/python3.10/site-packages/ray/_private/worker.py", line 2563, in get
    raise value.as_instanceof_cause()
ray.exceptions.RayTaskError(Error): [36mray::ImplicitFunc.train()[39m (pid=96914, ip=172.26.93.143, actor_id=17ff3c63127abe80f07c5dbb01000000, repr=train_algo)
  File "/data/gpfs/projects/punim1355/dalmiapriyam/predator-prey/.venv/lib/python3.10/site-packages/wandb/sdk/wandb_init.py", line 189, in setup
    self._wl = wandb_setup.setup(settings=setup_settings)
  File "/data/gpfs/projects/punim1355/dalmiapriyam/predator-prey/.venv/lib/python3.10/site-packages/wandb/sdk/wandb_setup.py", line 327, in setup
    ret = _setup(settings=settings)
  File "/data/gpfs/projects/punim1355/dalmiapriyam/predator-prey/.venv/lib/python3.10/site-packages/wandb/sdk/wandb_setup.py", line 320, in _setup
    wl = _WandbSetup(settings=settings)
  File "/data/gpfs/projects/punim1355/dalmiapriyam/predator-prey/.venv/lib/python3.10/site-packages/wandb/sdk/wandb_setup.py", line 303, in __init__
    _WandbSetup._instance = _WandbSetup__WandbSetup(settings=settings, pid=pid)
  File "/data/gpfs/projects/punim1355/dalmiapriyam/predator-prey/.venv/lib/python3.10/site-packages/wandb/sdk/wandb_setup.py", line 114, in __init__
    self._setup()
  File "/data/gpfs/projects/punim1355/dalmiapriyam/predator-prey/.venv/lib/python3.10/site-packages/wandb/sdk/wandb_setup.py", line 250, in _setup
    self._setup_manager()
  File "/data/gpfs/projects/punim1355/dalmiapriyam/predator-prey/.venv/lib/python3.10/site-packages/wandb/sdk/wandb_setup.py", line 277, in _setup_manager
    self._manager = wandb_manager._Manager(settings=self._settings)
  File "/data/gpfs/projects/punim1355/dalmiapriyam/predator-prey/.venv/lib/python3.10/site-packages/wandb/sdk/wandb_manager.py", line 138, in __init__
    self._service.start()
  File "/data/gpfs/projects/punim1355/dalmiapriyam/predator-prey/.venv/lib/python3.10/site-packages/wandb/sdk/service/service.py", line 258, in start
    self._launch_server()
  File "/data/gpfs/projects/punim1355/dalmiapriyam/predator-prey/.venv/lib/python3.10/site-packages/wandb/sdk/service/service.py", line 164, in _launch_server
    with tempfile.TemporaryDirectory() as tmpdir:
  File "/apps/easybuild-2022/easybuild/software/Compiler/GCCcore/11.3.0/Python/3.10.4/lib/python3.10/tempfile.py", line 796, in __init__
    self.name = mkdtemp(suffix, prefix, dir)
  File "/apps/easybuild-2022/easybuild/software/Compiler/GCCcore/11.3.0/Python/3.10.4/lib/python3.10/tempfile.py", line 368, in mkdtemp
    _os.mkdir(file, 0o700)
FileNotFoundError: [Errno 2] No such file or directory: '/tmp/tmp6cbh7esu'

The above exception was the direct cause of the following exception:

[36mray::ImplicitFunc.train()[39m (pid=96914, ip=172.26.93.143, actor_id=17ff3c63127abe80f07c5dbb01000000, repr=train_algo)
  File "/data/gpfs/projects/punim1355/dalmiapriyam/predator-prey/.venv/lib/python3.10/site-packages/ray/tune/trainable/trainable.py", line 342, in train
    raise skipped from exception_cause(skipped)
  File "/data/gpfs/projects/punim1355/dalmiapriyam/predator-prey/.venv/lib/python3.10/site-packages/ray/air/_internal/util.py", line 91, in run
    self._ret = self._target(*self._args, **self._kwargs)
  File "/data/gpfs/projects/punim1355/dalmiapriyam/predator-prey/.venv/lib/python3.10/site-packages/ray/tune/trainable/function_trainable.py", line 115, in <lambda>
    training_func=lambda: self._trainable_func(self.config),
  File "/data/gpfs/projects/punim1355/dalmiapriyam/predator-prey/.venv/lib/python3.10/site-packages/ray/tune/trainable/function_trainable.py", line 332, in _trainable_func
    output = fn()
  File "/data/gpfs/projects/punim1355/dalmiapriyam/predator-prey/./train.py", line 211, in train_algo
    wandb.init(
  File "/data/gpfs/projects/punim1355/dalmiapriyam/predator-prey/.venv/lib/python3.10/site-packages/wandb/sdk/wandb_init.py", line 1204, in init
    raise Error("An unexpected error occurred") from error_seen
wandb.errors.Error: An unexpected error occurred
2023-12-06 22:48:59,218	ERROR tune_controller.py:1383 -- Trial task failed for trial train_algo_64c6a_00014
Traceback (most recent call last):
  File "/data/gpfs/projects/punim1355/dalmiapriyam/predator-prey/.venv/lib/python3.10/site-packages/ray/air/execution/_internal/event_manager.py", line 110, in resolve_future
    result = ray.get(future)
  File "/data/gpfs/projects/punim1355/dalmiapriyam/predator-prey/.venv/lib/python3.10/site-packages/ray/_private/auto_init_hook.py", line 24, in auto_init_wrapper
    return fn(*args, **kwargs)
  File "/data/gpfs/projects/punim1355/dalmiapriyam/predator-prey/.venv/lib/python3.10/site-packages/ray/_private/client_mode_hook.py", line 103, in wrapper
    return func(*args, **kwargs)
  File "/data/gpfs/projects/punim1355/dalmiapriyam/predator-prey/.venv/lib/python3.10/site-packages/ray/_private/worker.py", line 2563, in get
    raise value.as_instanceof_cause()
ray.exceptions.RayTaskError(Error): [36mray::ImplicitFunc.train()[39m (pid=96900, ip=172.26.93.143, actor_id=9742a46bd9508eeae789d5ed01000000, repr=train_algo)
  File "/data/gpfs/projects/punim1355/dalmiapriyam/predator-prey/.venv/lib/python3.10/site-packages/wandb/sdk/wandb_init.py", line 189, in setup
    self._wl = wandb_setup.setup(settings=setup_settings)
  File "/data/gpfs/projects/punim1355/dalmiapriyam/predator-prey/.venv/lib/python3.10/site-packages/wandb/sdk/wandb_setup.py", line 327, in setup
    ret = _setup(settings=settings)
  File "/data/gpfs/projects/punim1355/dalmiapriyam/predator-prey/.venv/lib/python3.10/site-packages/wandb/sdk/wandb_setup.py", line 320, in _setup
    wl = _WandbSetup(settings=settings)
  File "/data/gpfs/projects/punim1355/dalmiapriyam/predator-prey/.venv/lib/python3.10/site-packages/wandb/sdk/wandb_setup.py", line 303, in __init__
    _WandbSetup._instance = _WandbSetup__WandbSetup(settings=settings, pid=pid)
  File "/data/gpfs/projects/punim1355/dalmiapriyam/predator-prey/.venv/lib/python3.10/site-packages/wandb/sdk/wandb_setup.py", line 114, in __init__
    self._setup()
  File "/data/gpfs/projects/punim1355/dalmiapriyam/predator-prey/.venv/lib/python3.10/site-packages/wandb/sdk/wandb_setup.py", line 250, in _setup
    self._setup_manager()
  File "/data/gpfs/projects/punim1355/dalmiapriyam/predator-prey/.venv/lib/python3.10/site-packages/wandb/sdk/wandb_setup.py", line 277, in _setup_manager
    self._manager = wandb_manager._Manager(settings=self._settings)
  File "/data/gpfs/projects/punim1355/dalmiapriyam/predator-prey/.venv/lib/python3.10/site-packages/wandb/sdk/wandb_manager.py", line 138, in __init__
    self._service.start()
  File "/data/gpfs/projects/punim1355/dalmiapriyam/predator-prey/.venv/lib/python3.10/site-packages/wandb/sdk/service/service.py", line 258, in start
    self._launch_server()
  File "/data/gpfs/projects/punim1355/dalmiapriyam/predator-prey/.venv/lib/python3.10/site-packages/wandb/sdk/service/service.py", line 164, in _launch_server
    with tempfile.TemporaryDirectory() as tmpdir:
  File "/apps/easybuild-2022/easybuild/software/Compiler/GCCcore/11.3.0/Python/3.10.4/lib/python3.10/tempfile.py", line 796, in __init__
    self.name = mkdtemp(suffix, prefix, dir)
  File "/apps/easybuild-2022/easybuild/software/Compiler/GCCcore/11.3.0/Python/3.10.4/lib/python3.10/tempfile.py", line 368, in mkdtemp
    _os.mkdir(file, 0o700)
FileNotFoundError: [Errno 2] No such file or directory: '/tmp/tmp90bjg2_o'

The above exception was the direct cause of the following exception:

[36mray::ImplicitFunc.train()[39m (pid=96900, ip=172.26.93.143, actor_id=9742a46bd9508eeae789d5ed01000000, repr=train_algo)
  File "/data/gpfs/projects/punim1355/dalmiapriyam/predator-prey/.venv/lib/python3.10/site-packages/ray/tune/trainable/trainable.py", line 342, in train
    raise skipped from exception_cause(skipped)
  File "/data/gpfs/projects/punim1355/dalmiapriyam/predator-prey/.venv/lib/python3.10/site-packages/ray/air/_internal/util.py", line 91, in run
    self._ret = self._target(*self._args, **self._kwargs)
  File "/data/gpfs/projects/punim1355/dalmiapriyam/predator-prey/.venv/lib/python3.10/site-packages/ray/tune/trainable/function_trainable.py", line 115, in <lambda>
    training_func=lambda: self._trainable_func(self.config),
  File "/data/gpfs/projects/punim1355/dalmiapriyam/predator-prey/.venv/lib/python3.10/site-packages/ray/tune/trainable/function_trainable.py", line 332, in _trainable_func
    output = fn()
  File "/data/gpfs/projects/punim1355/dalmiapriyam/predator-prey/./train.py", line 211, in train_algo
    wandb.init(
  File "/data/gpfs/projects/punim1355/dalmiapriyam/predator-prey/.venv/lib/python3.10/site-packages/wandb/sdk/wandb_init.py", line 1204, in init
    raise Error("An unexpected error occurred") from error_seen
wandb.errors.Error: An unexpected error occurred
2023-12-06 22:48:59,235	ERROR tune_controller.py:1383 -- Trial task failed for trial train_algo_64c6a_00003
Traceback (most recent call last):
  File "/data/gpfs/projects/punim1355/dalmiapriyam/predator-prey/.venv/lib/python3.10/site-packages/ray/air/execution/_internal/event_manager.py", line 110, in resolve_future
    result = ray.get(future)
  File "/data/gpfs/projects/punim1355/dalmiapriyam/predator-prey/.venv/lib/python3.10/site-packages/ray/_private/auto_init_hook.py", line 24, in auto_init_wrapper
    return fn(*args, **kwargs)
  File "/data/gpfs/projects/punim1355/dalmiapriyam/predator-prey/.venv/lib/python3.10/site-packages/ray/_private/client_mode_hook.py", line 103, in wrapper
    return func(*args, **kwargs)
  File "/data/gpfs/projects/punim1355/dalmiapriyam/predator-prey/.venv/lib/python3.10/site-packages/ray/_private/worker.py", line 2563, in get
    raise value.as_instanceof_cause()
ray.exceptions.RayTaskError(Error): [36mray::ImplicitFunc.train()[39m (pid=96889, ip=172.26.93.143, actor_id=98745208c6e622a822b0ed0501000000, repr=train_algo)
  File "/data/gpfs/projects/punim1355/dalmiapriyam/predator-prey/.venv/lib/python3.10/site-packages/wandb/sdk/wandb_init.py", line 189, in setup
    self._wl = wandb_setup.setup(settings=setup_settings)
  File "/data/gpfs/projects/punim1355/dalmiapriyam/predator-prey/.venv/lib/python3.10/site-packages/wandb/sdk/wandb_setup.py", line 327, in setup
    ret = _setup(settings=settings)
  File "/data/gpfs/projects/punim1355/dalmiapriyam/predator-prey/.venv/lib/python3.10/site-packages/wandb/sdk/wandb_setup.py", line 320, in _setup
    wl = _WandbSetup(settings=settings)
  File "/data/gpfs/projects/punim1355/dalmiapriyam/predator-prey/.venv/lib/python3.10/site-packages/wandb/sdk/wandb_setup.py", line 303, in __init__
    _WandbSetup._instance = _WandbSetup__WandbSetup(settings=settings, pid=pid)
  File "/data/gpfs/projects/punim1355/dalmiapriyam/predator-prey/.venv/lib/python3.10/site-packages/wandb/sdk/wandb_setup.py", line 114, in __init__
    self._setup()
  File "/data/gpfs/projects/punim1355/dalmiapriyam/predator-prey/.venv/lib/python3.10/site-packages/wandb/sdk/wandb_setup.py", line 250, in _setup
    self._setup_manager()
  File "/data/gpfs/projects/punim1355/dalmiapriyam/predator-prey/.venv/lib/python3.10/site-packages/wandb/sdk/wandb_setup.py", line 277, in _setup_manager
    self._manager = wandb_manager._Manager(settings=self._settings)
  File "/data/gpfs/projects/punim1355/dalmiapriyam/predator-prey/.venv/lib/python3.10/site-packages/wandb/sdk/wandb_manager.py", line 138, in __init__
    self._service.start()
  File "/data/gpfs/projects/punim1355/dalmiapriyam/predator-prey/.venv/lib/python3.10/site-packages/wandb/sdk/service/service.py", line 258, in start
    self._launch_server()
  File "/data/gpfs/projects/punim1355/dalmiapriyam/predator-prey/.venv/lib/python3.10/site-packages/wandb/sdk/service/service.py", line 164, in _launch_server
    with tempfile.TemporaryDirectory() as tmpdir:
  File "/apps/easybuild-2022/easybuild/software/Compiler/GCCcore/11.3.0/Python/3.10.4/lib/python3.10/tempfile.py", line 796, in __init__
    self.name = mkdtemp(suffix, prefix, dir)
  File "/apps/easybuild-2022/easybuild/software/Compiler/GCCcore/11.3.0/Python/3.10.4/lib/python3.10/tempfile.py", line 368, in mkdtemp
    _os.mkdir(file, 0o700)
FileNotFoundError: [Errno 2] No such file or directory: '/tmp/tmprjmmusy9'

The above exception was the direct cause of the following exception:

[36mray::ImplicitFunc.train()[39m (pid=96889, ip=172.26.93.143, actor_id=98745208c6e622a822b0ed0501000000, repr=train_algo)
  File "/data/gpfs/projects/punim1355/dalmiapriyam/predator-prey/.venv/lib/python3.10/site-packages/ray/tune/trainable/trainable.py", line 342, in train
    raise skipped from exception_cause(skipped)
  File "/data/gpfs/projects/punim1355/dalmiapriyam/predator-prey/.venv/lib/python3.10/site-packages/ray/air/_internal/util.py", line 91, in run
    self._ret = self._target(*self._args, **self._kwargs)
  File "/data/gpfs/projects/punim1355/dalmiapriyam/predator-prey/.venv/lib/python3.10/site-packages/ray/tune/trainable/function_trainable.py", line 115, in <lambda>
    training_func=lambda: self._trainable_func(self.config),
  File "/data/gpfs/projects/punim1355/dalmiapriyam/predator-prey/.venv/lib/python3.10/site-packages/ray/tune/trainable/function_trainable.py", line 332, in _trainable_func
    output = fn()
  File "/data/gpfs/projects/punim1355/dalmiapriyam/predator-prey/./train.py", line 211, in train_algo
    wandb.init(
  File "/data/gpfs/projects/punim1355/dalmiapriyam/predator-prey/.venv/lib/python3.10/site-packages/wandb/sdk/wandb_init.py", line 1204, in init
    raise Error("An unexpected error occurred") from error_seen
wandb.errors.Error: An unexpected error occurred
